<?xml version="1.0" encoding="UTF-8"?>
<robot xmlns:xacro="http://wiki.ros.org/xacro" name="texture_cube">

    

  <link name="texture_cube">
    <visual>
      <geometry>
        <box size="0.3 1.0 1.0"/>
      </geometry>
      <origin xyz="0.5 0.5 0.15" rpy="0 0 0"/>
    </visual>

    <inertial>
      <origin xyz="0.5 0.5 0.15" rpy="0 0 0"/>
      <mass value="1.0"/>
      <inertia ixx="0.01" ixy="0.0" ixz="0.0"
               iyy="0.01" iyz="0.0"
               izz="0.01"/>
    </inertial>

  </link>

  <joint name="texture_cube_to_rrr_shoulder" type="revolute">
    <parent link="texture_cube"/>
    <child link="rrr_shoulder_link"/>
    <origin xyz="0.0 0.0 0.3" rpy="0 0 0"/>
    <axis xyz="0 0 1"/>
    <limit effort="20.0" velocity="2.0" lower="-3.14" upper="3.14"/>
  </joint>

  <link name="rrr_shoulder_link">
    <visual>
      <geometry>
        <cylinder radius="0.08" length="0.25"/>
      </geometry>
      <origin xyz="0 0 0.125" rpy="0 0 0"/>
    </visual>
    <inertial>
      <origin xyz="0 0 0.125" rpy="0 0 0"/>
      <mass value="0.5"/>
      <inertia ixx="0.002" ixy="0.0" ixz="0.0"
               iyy="0.002" iyz="0.0"
               izz="0.0015"/>
    </inertial>
  </link>

  <joint name="rrr_shoulder_to_elbow" type="revolute">
    <parent link="rrr_shoulder_link"/>
    <child link="rrr_elbow_link"/>
    <origin xyz="0 0 0.25" rpy="0 0 0"/>
    <axis xyz="0 1 0"/>
    <limit effort="15.0" velocity="1.8" lower="-2.0" upper="2.0"/>
  </joint>

  <link name="rrr_elbow_link">
    <visual>
      <geometry>
        <box size="0.2 0.08 0.4"/>
      </geometry>
      <origin xyz="0.1 0 0.2" rpy="0 0 0"/>
    </visual>
    <inertial>
      <origin xyz="0.1 0 0.2" rpy="0 0 0"/>
      <mass value="0.4"/>
      <inertia ixx="0.0015" ixy="0.0" ixz="0.0"
               iyy="0.0015" iyz="0.0"
               izz="0.0012"/>
    </inertial>
  </link>

  <joint name="rrr_elbow_to_wrist" type="revolute">
    <parent link="rrr_elbow_link"/>
    <child link="rrr_wrist_link"/>
    <origin xyz="0.2 0 0.4" rpy="0 0 0"/>
    <axis xyz="0 1 0"/>
    <limit effort="10.0" velocity="1.5" lower="-2.5" upper="2.5"/>
  </joint>

  <link name="rrr_wrist_link">
    <visual>
      <geometry>
        <cylinder radius="0.05" length="0.2"/>
      </geometry>
      <origin xyz="0 0 0.1" rpy="0 0 0"/>
    </visual>
    <inertial>
      <origin xyz="0 0 0.1" rpy="0 0 0"/>
      <mass value="0.2"/>
      <inertia ixx="0.0004" ixy="0.0" ixz="0.0"
               iyy="0.0004" iyz="0.0"
               izz="0.0003"/>
    </inertial>
  </link>

  <joint name="texture_cube_to_sensor_mount" type="fixed">
    <parent link="texture_cube"/>
    <child link="sensor_mount"/>
    <origin xyz="0.0 0.0 0.5" rpy="0 0 0"/>
  </joint>

  <link name="sensor_mount">
    <visual>
      <geometry>
        <cylinder radius="0.1" length="0.2"/>
      </geometry>
      <origin xyz="0 0 0.1" rpy="0 0 0"/>
    </visual>
    <inertial>
      <origin xyz="0 0 0.1" rpy="0 0 0"/>
      <mass value="0.2"/>
      <inertia ixx="0.001" ixy="0.0" ixz="0.0"
               iyy="0.001" iyz="0.0"
               izz="0.0008"/>
    </inertial>
  </link>

  <joint name="sensor_mount_to_antenna" type="continuous">
    <parent link="sensor_mount"/>
    <child link="antenna"/>
    <origin xyz="0 0 0.2" rpy="0 0 0"/>
    <axis xyz="0 0 1"/>
    <limit effort="2.0" velocity="1.5"/>
  </joint>

  <link name="antenna">
    <visual>
      <geometry>
        <cylinder radius="0.05" length="0.4"/>
      </geometry>
      <origin xyz="0 0 0.2" rpy="0 0 0"/>
      <material name="antenna_material">
        <color rgba="0.3 0.3 0.9 1.0"/>
      </material>
    </visual>
    <collision>
      <geometry>
        <cylinder radius="0.05" length="0.4"/>
      </geometry>
      <origin xyz="0 0 0.2" rpy="0 0 0"/>
    </collision>
    <inertial>
      <origin xyz="0 0 0.2" rpy="0 0 0"/>
      <mass value="0.1"/>
      <inertia ixx="0.0005" ixy="0.0" ixz="0.0"
               iyy="0.0005" iyz="0.0"
               izz="0.0002"/>
    </inertial>
  </link>

</robot>
