<?xml version="1.0"?>
<robot xmlns:xacro="http://www.ros.org/wiki/xacro" name="composite">
<xacro:include filename="/home/bam/bam_ws/src/bam_machine/bam/descriptions/urdf/common.xacro"/>

  <!--
    Auto-generated Composite URDF
    Generated for: 4 descriptions, 5 custom joints, 2 custom links
    
    Note: This URDF was generated by expanding each description macro separately
    to avoid namespace conflicts, then combining the expanded XML.
  -->

  <!-- Start of macro 0: ArmRobotDescription (type=) -->
<!--
    Generic macro to compose an arm macro and a hand macro.

    Assumptions:
    - The arm macro accepts at least: prefix
    - The hand macro accepts at least: parent, prefix
    - The hand macro will attach its base to the provided parent link

    Notes:
    - Use xacro:call for dynamic macro names.
    - Include files are passed in as absolute paths so they can live in different packages.
  -->
  <!-- links -  main serial chain -->
  <!-- base_link_ur serves as the root of the robot's kinematic tree. It follows REP-103
        conventions (i.e., X+ forward, Y+ left, Z+ up).
        Since some kinematic solvers forbid having inertia values attached to a root link, we've
        added the base_link_inertia link that carries the visual, collision and inertia
        information.
    -->
  <!-- Rename base_link to base_link_ur so you can add another base_link_ur outside... -->
  <link name="front_left_base_link_ur"/>
  <link name="front_left_base_link_inertia">
    <visual>
      <origin rpy="0.0 0.0 3.141592653589793" xyz="0.0 0.0 0.0"/>
      <geometry>
        <mesh filename="package://ur_description/meshes/ur5e/visual/base.dae"/>
      </geometry>
    </visual>
    <collision>
      <origin rpy="0.0 0.0 3.141592653589793" xyz="0.0 0.0 0.0"/>
      <geometry>
        <mesh filename="package://ur_description/meshes/ur5e/collision/base.stl"/>
      </geometry>
    </collision>
    <inertial>
      <mass value="4.0"/>
      <origin rpy="0 0 0" xyz="0 0 0"/>
      <inertia ixx="0.00443333156" ixy="0.0" ixz="0.0" iyy="0.00443333156" iyz="0.0" izz="0.0072"/>
    </inertial>
  </link>
  <link name="front_left_shoulder_link">
    <visual>
      <origin rpy="0.0 0.0 3.141592653589793" xyz="0.0 0.0 0.0"/>
      <geometry>
        <mesh filename="package://ur_description/meshes/ur5e/visual/shoulder.dae"/>
      </geometry>
    </visual>
    <collision>
      <origin rpy="0.0 0.0 3.141592653589793" xyz="0.0 0.0 0.0"/>
      <geometry>
        <mesh filename="package://ur_description/meshes/ur5e/collision/shoulder.stl"/>
      </geometry>
    </collision>
    <inertial>
      <mass value="3.761"/>
      <origin rpy="1.570796326794897 0 0" xyz="0.0 -0.00193 -0.02561"/>
      <inertia ixx="0.0070021" ixy="7.3e-07" ixz="-1.053e-05" iyy="0.00648091" iyz="0.00049994" izz="0.00657286"/>
    </inertial>
  </link>
  <link name="front_left_upper_arm_link">
    <visual>
      <origin rpy="1.5707963267948966 0.0 -1.5707963267948966" xyz="0.0 0.0 0.138"/>
      <geometry>
        <mesh filename="package://ur_description/meshes/ur5e/visual/upperarm.dae"/>
      </geometry>
    </visual>
    <collision>
      <origin rpy="1.5707963267948966 0.0 -1.5707963267948966" xyz="0.0 0.0 0.138"/>
      <geometry>
        <mesh filename="package://ur_description/meshes/ur5e/collision/upperarm.stl"/>
      </geometry>
    </collision>
    <inertial>
      <mass value="8.058"/>
      <origin rpy="0 0 0" xyz="-0.2125 0.0 0.11336"/>
      <inertia ixx="0.01505885" ixy="-5.4e-05" ixz="5.63e-06" iyy="0.33388086" iyz="-1.81e-06" izz="0.33247207"/>
    </inertial>
  </link>
  <link name="front_left_forearm_link">
    <visual>
      <origin rpy="1.5707963267948966 0.0 -1.5707963267948966" xyz="0.0 0.0 0.007"/>
      <geometry>
        <mesh filename="package://ur_description/meshes/ur5e/visual/forearm.dae"/>
      </geometry>
    </visual>
    <collision>
      <origin rpy="1.5707963267948966 0.0 -1.5707963267948966" xyz="0.0 0.0 0.007"/>
      <geometry>
        <mesh filename="package://ur_description/meshes/ur5e/collision/forearm.stl"/>
      </geometry>
    </collision>
    <inertial>
      <mass value="2.846"/>
      <origin rpy="0 0 0" xyz="-0.2422 0.0 0.0265"/>
      <inertia ixx="0.00399632" ixy="-1.365e-05" ixz="0.00137272" iyy="0.07879254" iyz="-6.6e-06" izz="0.0784851"/>
    </inertial>
  </link>
  <link name="front_left_wrist_1_link">
    <visual>
      <origin rpy="1.5707963267948966 0.0 0.0" xyz="0.0 0.0 -0.127"/>
      <geometry>
        <mesh filename="package://ur_description/meshes/ur5e/visual/wrist1.dae"/>
      </geometry>
    </visual>
    <collision>
      <origin rpy="1.5707963267948966 0.0 0.0" xyz="0.0 0.0 -0.127"/>
      <geometry>
        <mesh filename="package://ur_description/meshes/ur5e/collision/wrist1.stl"/>
      </geometry>
    </collision>
    <inertial>
      <mass value="1.37"/>
      <origin rpy="1.570796326794897 0 0" xyz="0.0 -0.01634 -0.0018"/>
      <inertia ixx="0.00165491" ixy="-2.82e-06" ixz="-4.38e-06" iyy="0.00135962" iyz="0.00010157" izz="0.00126279"/>
    </inertial>
  </link>
  <link name="front_left_wrist_2_link">
    <visual>
      <origin rpy="0.0 0.0 0.0" xyz="0.0 0.0 -0.0997"/>
      <geometry>
        <mesh filename="package://ur_description/meshes/ur5e/visual/wrist2.dae"/>
      </geometry>
    </visual>
    <collision>
      <origin rpy="0.0 0.0 0.0" xyz="0.0 0.0 -0.0997"/>
      <geometry>
        <mesh filename="package://ur_description/meshes/ur5e/collision/wrist2.stl"/>
      </geometry>
    </collision>
    <inertial>
      <mass value="1.3"/>
      <origin rpy="-1.570796326794897 0 0" xyz="0.0 0.01634 -0.0018"/>
      <inertia ixx="0.00135617" ixy="-2.74e-06" ixz="4.44e-06" iyy="0.00127827" iyz="-5.048e-05" izz="0.00096614"/>
    </inertial>
  </link>
  <link name="front_left_wrist_3_link">
    <visual>
      <origin rpy="1.5707963267948966 0.0 0.0" xyz="0.0 0.0 -0.0989"/>
      <geometry>
        <mesh filename="package://ur_description/meshes/ur5e/visual/wrist3.dae"/>
      </geometry>
    </visual>
    <collision>
      <origin rpy="1.5707963267948966 0.0 0.0" xyz="0.0 0.0 -0.0989"/>
      <geometry>
        <mesh filename="package://ur_description/meshes/ur5e/collision/wrist3.stl"/>
      </geometry>
    </collision>
    <inertial>
      <mass value="0.365"/>
      <origin rpy="0 0 0" xyz="0.0 0.0 -0.001159"/>
      <inertia ixx="0.00018694" ixy="6e-08" ixz="-1.7e-07" iyy="0.00018908" iyz="-9.2e-07" izz="0.00025756"/>
    </inertial>
  </link>
  <!-- base_joint fixes base_link_ur to the environment -->
  <!-- <joint name="${tf_prefix}base_joint" type="fixed">
      <xacro:insert_block name="origin" />
      <parent link="${parent}" />
      <child link="${tf_prefix}base_link_ur" />
    </joint> -->
  <!-- joints - main serial chain -->
  <joint name="front_left_base_link_ur-base_link_inertia" type="fixed">
    <parent link="front_left_base_link_ur"/>
    <child link="front_left_base_link_inertia"/>
    <!-- 'base_link_ur' is REP-103 aligned (so X+ forward), while the internal
           frames of the robot/controller have X+ pointing backwards.
           Use the joint between 'base_link_ur' and 'base_link_inertia' (a dummy
           link/frame) to introduce the necessary rotation over Z (of pi rad).
      -->
    <origin rpy="0 0 3.141592653589793" xyz="0 0 0"/>
  </joint>
  <joint name="front_left_shoulder_pan_joint" type="revolute">
    <parent link="front_left_base_link_inertia"/>
    <child link="front_left_shoulder_link"/>
    <origin rpy="0 0 0" xyz="0 0 0.1625"/>
    <axis xyz="0 0 1"/>
    <limit effort="150.0" lower="-3.141592653589793" upper="3.141592653589793" velocity="3.141592653589793"/>
    <!-- Increase friction in lower joints, they seem to be osscilating alot in sim, and we know friction increases with load -->
    <dynamics damping="0.05" friction="0.3"/>
  </joint>
  <joint name="front_left_shoulder_lift_joint" type="revolute">
    <parent link="front_left_shoulder_link"/>
    <child link="front_left_upper_arm_link"/>
    <origin rpy="1.570796327 0 0" xyz="0 0 0"/>
    <axis xyz="0 0 1"/>
    <limit effort="150.0" lower="-3.141592653589793" upper="3.141592653589793" velocity="3.141592653589793"/>
    <dynamics damping="0.05" friction="0.3"/>
  </joint>
  <joint name="front_left_elbow_joint" type="revolute">
    <parent link="front_left_upper_arm_link"/>
    <child link="front_left_forearm_link"/>
    <origin rpy="0 0 0" xyz="-0.425 0 0"/>
    <axis xyz="0 0 1"/>
    <limit effort="150.0" lower="-3.141592653589793" upper="3.141592653589793" velocity="3.141592653589793"/>
    <dynamics damping="0.05" friction="0.1"/>
  </joint>
  <joint name="front_left_wrist_1_joint" type="revolute">
    <parent link="front_left_forearm_link"/>
    <child link="front_left_wrist_1_link"/>
    <origin rpy="0 0 0" xyz="-0.3922 0 0.1333"/>
    <axis xyz="0 0 1"/>
    <limit effort="28.0" lower="-4.71238898038469" upper="1.5707963267948966" velocity="3.141592653589793"/>
    <dynamics damping="0.05" friction="0.1"/>
  </joint>
  <joint name="front_left_wrist_2_joint" type="revolute">
    <parent link="front_left_wrist_1_link"/>
    <child link="front_left_wrist_2_link"/>
    <origin rpy="1.570796327 0 0" xyz="0 -0.0997 -2.044881182297852e-11"/>
    <axis xyz="0 0 1"/>
    <limit effort="28.0" lower="-4.71238898038469" upper="1.5707963267948966" velocity="3.141592653589793"/>
    <dynamics damping="0.05" friction="0.1"/>
  </joint>
  <joint name="front_left_wrist_3_joint" type="revolute">
    <parent link="front_left_wrist_2_link"/>
    <child link="front_left_wrist_3_link"/>
    <origin rpy="1.570796326589793 3.141592653589793 3.141592653589793" xyz="0 0.0996 -2.042830148012698e-11"/>
    <axis xyz="0 0 1"/>
    <limit effort="28.0" lower="-3.141592653589793" upper="3.141592653589793" velocity="3.141592653589793"/>
    <dynamics damping="0.05" friction="0.1"/>
  </joint>
  <!-- The FT Frame has the same pose as tool0_flip, but we add tool0_flip because its more verbose -->
  <link name="front_left_ft_frame"/>
  <joint name="front_left_wrist_3_link-ft_frame" type="fixed">
    <parent link="front_left_wrist_3_link"/>
    <child link="front_left_ft_frame"/>
    <origin rpy="3.141592653589793 0 0" xyz="0 0 0"/>
  </joint>
  <!-- ROS-Industrial 'base' frame - base_link_ur to UR 'Base' Coordinates transform -->
  <link name="front_left_base"/>
  <joint name="front_left_base_link_ur-base_fixed_joint" type="fixed">
    <!-- Note the rotation over Z of pi radians - as base_link_ur is REP-103
           aligned (i.e., has X+ forward, Y+ left and Z+ up), this is needed
           to correctly align 'base' with the 'Base' coordinate system of
           the UR controller.
      -->
    <origin rpy="0 0 3.141592653589793" xyz="0 0 0"/>
    <parent link="front_left_base_link_ur"/>
    <child link="front_left_base"/>
  </joint>
  <!-- ROS-Industrial 'flange' frame - attachment point for EEF models -->
  <link name="front_left_flange"/>
  <joint name="front_left_wrist_3-flange" type="fixed">
    <parent link="front_left_wrist_3_link"/>
    <child link="front_left_flange"/>
    <origin rpy="0 -1.5707963267948966 -1.5707963267948966" xyz="0 0 0"/>
  </joint>
  <!-- ROS-Industrial 'tool0' frame - all-zeros tool frame -->
  <link name="front_left_tool0"/>
  <joint name="front_left_flange-tool0" type="fixed">
    <!-- default toolframe - X+ left, Y+ up, Z+ front -->
    <origin rpy="1.5707963267948966 0 1.5707963267948966" xyz="0 0 0"/>
    <parent link="front_left_flange"/>
    <child link="front_left_tool0"/>
  </joint>
  <!-- https://github.com/ros-industrial/universal_robot/pull/506/files -->
  <!-- Link from original ur_kinematics, see notes in the ur_ros1 package-->
  <link name="front_left_ee_link"/>
  <joint name="front_left_ee_fixed_joint" type="fixed">
    <parent link="front_left_wrist_3_link"/>
    <child link="front_left_ee_link"/>
    <origin rpy="0.0 -1.5707963267948966 1.5707963267948966" xyz="0 0 0"/>
  </joint>
  <!-- For testing IK offset converions, helpful to have a offset tcp link -->
  <link name="front_left_tcp_world_test"/>
  <joint name="front_left_tool0_to_tcp_world_test" type="fixed">
    <parent link="front_left_tool0"/>
    <child link="front_left_tcp_world_test"/>
    <!-- Go forward a bit along z and flip around -->
    <origin rpy="3.141592653589793 0 0" xyz="0 0 0.1"/>
  </joint>
  <link name="front_left_tool0_flip"/>
  <joint name="front_left_tool0-tool0flip" type="fixed">
    <origin rpy="3.141592653589793 0 0" xyz="0 0 0"/>
    <parent link="front_left_tool0"/>
    <child link="front_left_tool0_flip"/>
  </joint>
  <joint name="front_left_arm_to_hand_mount" type="fixed">
    <origin rpy="0 0 0" xyz="0 0 0"/>
    <parent link="front_left_tool0"/>
    <child link="front_left_robotiq_85_base_link"/>
  </joint>
  <link name="front_left_robotiq_85_base_link">
    <visual>
      <geometry>
        <mesh filename="package://robotiq_description/meshes/visual/2f_85/robotiq_base.dae"/>
      </geometry>
    </visual>
    <collision>
      <geometry>
        <mesh filename="package://robotiq_description/meshes/collision/2f_85/robotiq_base.stl"/>
      </geometry>
    </collision>
    <inertial>
      <origin rpy="0 0 0" xyz="0.0 2.274e-05 0.03232288"/>
      <mass value="6.6320197e-01"/>
      <inertia ixx="5.1617816e-04" ixy="2.936e-8" ixz="0.0" iyy="5.8802208e-04" iyz="-3.2296e-7" izz="3.9462776e-04"/>
    </inertial>
  </link>
  <link name="front_left_robotiq_85_left_knuckle_link">
    <visual>
      <geometry>
        <mesh filename="package://robotiq_description/meshes/visual/2f_85/left_knuckle.dae"/>
      </geometry>
    </visual>
    <collision>
      <geometry>
        <mesh filename="package://robotiq_description/meshes/collision/2f_85/left_knuckle.stl"/>
      </geometry>
    </collision>
    <inertial>
      <origin rpy="0 0 0" xyz="0.01213197 0.0002 -0.00058647"/>
      <mass value="1.384773208e-02"/>
      <inertia ixx="3.5232e-7" ixy="0.0" ixz="1.1744e-7" iyy="2.31944e-6" iyz="0" izz="2.23136e-6"/>
    </inertial>
  </link>
  <link name="front_left_robotiq_85_right_knuckle_link">
    <visual>
      <geometry>
        <mesh filename="package://robotiq_description/meshes/visual/2f_85/right_knuckle.dae"/>
      </geometry>
    </visual>
    <collision>
      <geometry>
        <mesh filename="package://robotiq_description/meshes/collision/2f_85/right_knuckle.stl"/>
      </geometry>
    </collision>
    <inertial>
      <origin rpy="0 0 0" xyz="-0.01213197 0.0002 -0.00058647"/>
      <mass value="1.384773208e-02"/>
      <inertia ixx="3.5232e-7" ixy="0.0" ixz="-1.1744e-7" iyy="2.31944e-6" iyz="0.0" izz="2.23136e-6"/>
    </inertial>
  </link>
  <link name="front_left_robotiq_85_left_finger_link">
    <visual>
      <geometry>
        <mesh filename="package://robotiq_description/meshes/visual/2f_85/left_finger.dae"/>
      </geometry>
    </visual>
    <collision>
      <geometry>
        <mesh filename="package://robotiq_description/meshes/collision/2f_85/left_finger.stl"/>
      </geometry>
    </collision>
    <inertial>
      <origin rpy="0 0 0" xyz="0.00346899 -0.00079447 0.01867121"/>
      <mass value="4.260376752e-02"/>
      <inertia ixx="1.385792000000000e-05" ixy="0.0" ixz="-2.17264e-06" iyy="1.183208e-05" iyz="0.0" izz="5.19672e-06"/>
    </inertial>
  </link>
  <link name="front_left_robotiq_85_right_finger_link">
    <visual>
      <geometry>
        <mesh filename="package://robotiq_description/meshes/visual/2f_85/right_finger.dae"/>
      </geometry>
    </visual>
    <collision>
      <geometry>
        <mesh filename="package://robotiq_description/meshes/collision/2f_85/right_finger.stl"/>
      </geometry>
    </collision>
    <inertial>
      <origin rpy="0 0 0" xyz="-0.00346899 -5.53e-06 0.01867121"/>
      <mass value="4.260376752000000e-02"/>
      <inertia ixx="1.385792e-05" ixy="0.0" ixz="2.17264e-06" iyy="1.183208e-05" iyz="0.0" izz="5.19672e-06"/>
    </inertial>
  </link>
  <link name="front_left_robotiq_85_left_inner_knuckle_link">
    <visual>
      <geometry>
        <mesh filename="package://robotiq_description/meshes/visual/2f_85/left_inner_knuckle.dae"/>
      </geometry>
    </visual>
    <collision>
      <geometry>
        <mesh filename="package://robotiq_description/meshes/collision/2f_85/left_inner_knuckle.stl"/>
      </geometry>
    </collision>
    <inertial>
      <origin rpy="0 0 0" xyz="0.01897699 0.00015001 0.02247101"/>
      <mass value="2.969376448e-02"/>
      <inertia ixx="9.57136e-06" ixy="0.0" ixz="-3.93424e-06" iyy="8.69056e-06" iyz="0.0" izz="8.19144e-06"/>
    </inertial>
  </link>
  <link name="front_left_robotiq_85_right_inner_knuckle_link">
    <visual>
      <geometry>
        <mesh filename="package://robotiq_description/meshes/visual/2f_85/right_inner_knuckle.dae"/>
      </geometry>
    </visual>
    <collision>
      <geometry>
        <mesh filename="package://robotiq_description/meshes/collision/2f_85/right_inner_knuckle.stl"/>
      </geometry>
    </collision>
    <inertial>
      <origin rpy="0 0 0" xyz="-0.01926824 5.001e-05 0.02222178"/>
      <mass value="2.969376448e-02"/>
      <inertia ixx="9.42456e-06" ixy="0.0" ixz="3.9636e-06" iyy="8.69056e-06" iyz="0.0" izz="8.33824e-06"/>
    </inertial>
  </link>
  <link name="front_left_robotiq_85_left_finger_tip_link">
    <visual>
      <geometry>
        <mesh filename="package://robotiq_description/meshes/visual/2f_85/left_finger_tip.dae"/>
      </geometry>
    </visual>
    <collision>
      <geometry>
        <mesh filename="package://robotiq_description/meshes/collision/2f_85/left_finger_tip.stl"/>
      </geometry>
      <surface>
        <friction>
          <ode>
            <mu1>100000.0</mu1>
            <mu2>100000.0</mu2>
          </ode>
        </friction>
        <contact>
          <ode>
            <kp>1e+5</kp>
            <kd>1</kd>
            <soft_cfm>0</soft_cfm>
            <soft_erp>0.2</soft_erp>
            <minDepth>0.002</minDepth>
            <maxVel>0</maxVel>
          </ode>
        </contact>
      </surface>
    </collision>
    <inertial>
      <origin rpy="0 0 0" xyz="-0.01456706 -0.0008 0.01649701"/>
      <mass value="4.268588744e-02"/>
      <inertia ixx="1.048152e-05" ixy="0.0" ixz="3.5232e-6" iyy="1.197888e-05" iyz="0.0" izz="4.22784e-06"/>
    </inertial>
  </link>
  <link name="front_left_robotiq_85_right_finger_tip_link">
    <visual>
      <geometry>
        <mesh filename="package://robotiq_description/meshes/visual/2f_85/right_finger_tip.dae"/>
      </geometry>
    </visual>
    <collision>
      <geometry>
        <mesh filename="package://robotiq_description/meshes/collision/2f_85/right_finger_tip.stl"/>
      </geometry>
      <surface>
        <friction>
          <ode>
            <mu1>100000.0</mu1>
            <mu2>100000.0</mu2>
          </ode>
        </friction>
        <contact>
          <ode>
            <kp>1e+5</kp>
            <kd>1</kd>
            <soft_cfm>0</soft_cfm>
            <soft_erp>0.2</soft_erp>
            <minDepth>0.002</minDepth>
            <maxVel>0</maxVel>
          </ode>
        </contact>
      </surface>
    </collision>
    <inertial>
      <origin rpy="0 0 0" xyz="0.01456706 5e-05 0.01649701"/>
      <mass value="4.268588744e-02"/>
      <inertia ixx="1.048152e-05" ixy="0.0" ixz="-3.5232e-06" iyy="1.197888e-05" iyz="0.0" izz="4.22784e-06"/>
    </inertial>
  </link>
  <!-- BUG ZILLA! https://github.com/stack-of-tasks/pinocchio/issues/2753 Alphabetical order screws it up.. -->
  <!-- Previously called, but switch for something higher in alphabetical order: ${prefix}robotiq_85_left_knuckle_joint -->
  <joint name="front_left_finger_joint" type="revolute">
    <parent link="front_left_robotiq_85_base_link"/>
    <child link="front_left_robotiq_85_left_knuckle_link"/>
    <axis xyz="0 -1 0"/>
    <origin rpy="0 0 0" xyz="0.03060114 0.0 0.05490452"/>
    <limit effort="50" lower="0.0" upper="0.8" velocity="0.5"/>
  </joint>
  <joint name="front_left_robotiq_85_right_knuckle_joint" type="revolute">
    <parent link="front_left_robotiq_85_base_link"/>
    <child link="front_left_robotiq_85_right_knuckle_link"/>
    <axis xyz="0 -1 0"/>
    <origin rpy="0 0 0" xyz="-0.03060114 0.0 0.05490452"/>
    <limit effort="50" lower="-0.8" upper="0.0" velocity="0.5"/>
    <mimic joint="front_left_finger_joint" multiplier="-1" offset="0"/>
  </joint>
  <joint name="front_left_robotiq_85_left_finger_joint" type="fixed">
    <parent link="front_left_robotiq_85_left_knuckle_link"/>
    <child link="front_left_robotiq_85_left_finger_link"/>
    <origin rpy="0 0 0" xyz="0.03152616 0.0 -0.00376347"/>
  </joint>
  <joint name="front_left_robotiq_85_right_finger_joint" type="fixed">
    <parent link="front_left_robotiq_85_right_knuckle_link"/>
    <child link="front_left_robotiq_85_right_finger_link"/>
    <origin rpy="0 0 0" xyz="-0.03152616 0.0 -0.00376347"/>
  </joint>
  <joint name="front_left_robotiq_85_left_inner_knuckle_joint" type="revolute">
    <parent link="front_left_robotiq_85_base_link"/>
    <child link="front_left_robotiq_85_left_inner_knuckle_link"/>
    <axis xyz="0 -1 0"/>
    <origin rpy="0 0 0" xyz="0.0127 0.0 0.06142"/>
    <mimic joint="front_left_finger_joint" multiplier="1" offset="0"/>
    <limit effort="50" lower="-6.283185307179586" upper="6.283185307179586" velocity="0.5"/>
  </joint>
  <joint name="front_left_robotiq_85_right_inner_knuckle_joint" type="revolute">
    <parent link="front_left_robotiq_85_base_link"/>
    <child link="front_left_robotiq_85_right_inner_knuckle_link"/>
    <axis xyz="0 -1 0"/>
    <origin rpy="0 0 0" xyz="-0.0127 0.0 0.06142"/>
    <mimic joint="front_left_finger_joint" multiplier="-1" offset="0"/>
    <limit effort="50" lower="-6.283185307179586" upper="6.283185307179586" velocity="0.5"/>
  </joint>
  <joint name="front_left_robotiq_85_left_finger_tip_joint" type="revolute">
    <parent link="front_left_robotiq_85_left_finger_link"/>
    <child link="front_left_robotiq_85_left_finger_tip_link"/>
    <axis xyz="0 -1 0"/>
    <origin rpy="0 0 0" xyz="0.00563134 0.0 0.04718515"/>
    <mimic joint="front_left_finger_joint" multiplier="-1" offset="0"/>
    <limit effort="50" lower="-6.283185307179586" upper="6.283185307179586" velocity="0.5"/>
  </joint>
  <joint name="front_left_robotiq_85_right_finger_tip_joint" type="revolute">
    <parent link="front_left_robotiq_85_right_finger_link"/>
    <child link="front_left_robotiq_85_right_finger_tip_link"/>
    <axis xyz="0 -1 0"/>
    <origin rpy="0 0 0" xyz="-0.00563134 0.0 0.04718515"/>
    <mimic joint="front_left_finger_joint" multiplier="1" offset="0"/>
    <limit effort="50" lower="-6.283185307179586" upper="6.283185307179586" velocity="0.5"/>
  </joint>
  <!-- End of macro 0 -->
  <!-- Start of macro 1: ArmRobotDescription (type=) -->
<!--
    Generic macro to compose an arm macro and a hand macro.

    Assumptions:
    - The arm macro accepts at least: prefix
    - The hand macro accepts at least: parent, prefix
    - The hand macro will attach its base to the provided parent link

    Notes:
    - Use xacro:call for dynamic macro names.
    - Include files are passed in as absolute paths so they can live in different packages.
  -->
  <!-- links -  main serial chain -->
  <!-- base_link_ur serves as the root of the robot's kinematic tree. It follows REP-103
        conventions (i.e., X+ forward, Y+ left, Z+ up).
        Since some kinematic solvers forbid having inertia values attached to a root link, we've
        added the base_link_inertia link that carries the visual, collision and inertia
        information.
    -->
  <!-- Rename base_link to base_link_ur so you can add another base_link_ur outside... -->
  <link name="front_right_base_link_ur"/>
  <link name="front_right_base_link_inertia">
    <visual>
      <origin rpy="0.0 0.0 3.141592653589793" xyz="0.0 0.0 0.0"/>
      <geometry>
        <mesh filename="package://ur_description/meshes/ur5e/visual/base.dae"/>
      </geometry>
    </visual>
    <collision>
      <origin rpy="0.0 0.0 3.141592653589793" xyz="0.0 0.0 0.0"/>
      <geometry>
        <mesh filename="package://ur_description/meshes/ur5e/collision/base.stl"/>
      </geometry>
    </collision>
    <inertial>
      <mass value="4.0"/>
      <origin rpy="0 0 0" xyz="0 0 0"/>
      <inertia ixx="0.00443333156" ixy="0.0" ixz="0.0" iyy="0.00443333156" iyz="0.0" izz="0.0072"/>
    </inertial>
  </link>
  <link name="front_right_shoulder_link">
    <visual>
      <origin rpy="0.0 0.0 3.141592653589793" xyz="0.0 0.0 0.0"/>
      <geometry>
        <mesh filename="package://ur_description/meshes/ur5e/visual/shoulder.dae"/>
      </geometry>
    </visual>
    <collision>
      <origin rpy="0.0 0.0 3.141592653589793" xyz="0.0 0.0 0.0"/>
      <geometry>
        <mesh filename="package://ur_description/meshes/ur5e/collision/shoulder.stl"/>
      </geometry>
    </collision>
    <inertial>
      <mass value="3.761"/>
      <origin rpy="1.570796326794897 0 0" xyz="0.0 -0.00193 -0.02561"/>
      <inertia ixx="0.0070021" ixy="7.3e-07" ixz="-1.053e-05" iyy="0.00648091" iyz="0.00049994" izz="0.00657286"/>
    </inertial>
  </link>
  <link name="front_right_upper_arm_link">
    <visual>
      <origin rpy="1.5707963267948966 0.0 -1.5707963267948966" xyz="0.0 0.0 0.138"/>
      <geometry>
        <mesh filename="package://ur_description/meshes/ur5e/visual/upperarm.dae"/>
      </geometry>
    </visual>
    <collision>
      <origin rpy="1.5707963267948966 0.0 -1.5707963267948966" xyz="0.0 0.0 0.138"/>
      <geometry>
        <mesh filename="package://ur_description/meshes/ur5e/collision/upperarm.stl"/>
      </geometry>
    </collision>
    <inertial>
      <mass value="8.058"/>
      <origin rpy="0 0 0" xyz="-0.2125 0.0 0.11336"/>
      <inertia ixx="0.01505885" ixy="-5.4e-05" ixz="5.63e-06" iyy="0.33388086" iyz="-1.81e-06" izz="0.33247207"/>
    </inertial>
  </link>
  <link name="front_right_forearm_link">
    <visual>
      <origin rpy="1.5707963267948966 0.0 -1.5707963267948966" xyz="0.0 0.0 0.007"/>
      <geometry>
        <mesh filename="package://ur_description/meshes/ur5e/visual/forearm.dae"/>
      </geometry>
    </visual>
    <collision>
      <origin rpy="1.5707963267948966 0.0 -1.5707963267948966" xyz="0.0 0.0 0.007"/>
      <geometry>
        <mesh filename="package://ur_description/meshes/ur5e/collision/forearm.stl"/>
      </geometry>
    </collision>
    <inertial>
      <mass value="2.846"/>
      <origin rpy="0 0 0" xyz="-0.2422 0.0 0.0265"/>
      <inertia ixx="0.00399632" ixy="-1.365e-05" ixz="0.00137272" iyy="0.07879254" iyz="-6.6e-06" izz="0.0784851"/>
    </inertial>
  </link>
  <link name="front_right_wrist_1_link">
    <visual>
      <origin rpy="1.5707963267948966 0.0 0.0" xyz="0.0 0.0 -0.127"/>
      <geometry>
        <mesh filename="package://ur_description/meshes/ur5e/visual/wrist1.dae"/>
      </geometry>
    </visual>
    <collision>
      <origin rpy="1.5707963267948966 0.0 0.0" xyz="0.0 0.0 -0.127"/>
      <geometry>
        <mesh filename="package://ur_description/meshes/ur5e/collision/wrist1.stl"/>
      </geometry>
    </collision>
    <inertial>
      <mass value="1.37"/>
      <origin rpy="1.570796326794897 0 0" xyz="0.0 -0.01634 -0.0018"/>
      <inertia ixx="0.00165491" ixy="-2.82e-06" ixz="-4.38e-06" iyy="0.00135962" iyz="0.00010157" izz="0.00126279"/>
    </inertial>
  </link>
  <link name="front_right_wrist_2_link">
    <visual>
      <origin rpy="0.0 0.0 0.0" xyz="0.0 0.0 -0.0997"/>
      <geometry>
        <mesh filename="package://ur_description/meshes/ur5e/visual/wrist2.dae"/>
      </geometry>
    </visual>
    <collision>
      <origin rpy="0.0 0.0 0.0" xyz="0.0 0.0 -0.0997"/>
      <geometry>
        <mesh filename="package://ur_description/meshes/ur5e/collision/wrist2.stl"/>
      </geometry>
    </collision>
    <inertial>
      <mass value="1.3"/>
      <origin rpy="-1.570796326794897 0 0" xyz="0.0 0.01634 -0.0018"/>
      <inertia ixx="0.00135617" ixy="-2.74e-06" ixz="4.44e-06" iyy="0.00127827" iyz="-5.048e-05" izz="0.00096614"/>
    </inertial>
  </link>
  <link name="front_right_wrist_3_link">
    <visual>
      <origin rpy="1.5707963267948966 0.0 0.0" xyz="0.0 0.0 -0.0989"/>
      <geometry>
        <mesh filename="package://ur_description/meshes/ur5e/visual/wrist3.dae"/>
      </geometry>
    </visual>
    <collision>
      <origin rpy="1.5707963267948966 0.0 0.0" xyz="0.0 0.0 -0.0989"/>
      <geometry>
        <mesh filename="package://ur_description/meshes/ur5e/collision/wrist3.stl"/>
      </geometry>
    </collision>
    <inertial>
      <mass value="0.365"/>
      <origin rpy="0 0 0" xyz="0.0 0.0 -0.001159"/>
      <inertia ixx="0.00018694" ixy="6e-08" ixz="-1.7e-07" iyy="0.00018908" iyz="-9.2e-07" izz="0.00025756"/>
    </inertial>
  </link>
  <!-- base_joint fixes base_link_ur to the environment -->
  <!-- <joint name="${tf_prefix}base_joint" type="fixed">
      <xacro:insert_block name="origin" />
      <parent link="${parent}" />
      <child link="${tf_prefix}base_link_ur" />
    </joint> -->
  <!-- joints - main serial chain -->
  <joint name="front_right_base_link_ur-base_link_inertia" type="fixed">
    <parent link="front_right_base_link_ur"/>
    <child link="front_right_base_link_inertia"/>
    <!-- 'base_link_ur' is REP-103 aligned (so X+ forward), while the internal
           frames of the robot/controller have X+ pointing backwards.
           Use the joint between 'base_link_ur' and 'base_link_inertia' (a dummy
           link/frame) to introduce the necessary rotation over Z (of pi rad).
      -->
    <origin rpy="0 0 3.141592653589793" xyz="0 0 0"/>
  </joint>
  <joint name="front_right_shoulder_pan_joint" type="revolute">
    <parent link="front_right_base_link_inertia"/>
    <child link="front_right_shoulder_link"/>
    <origin rpy="0 0 0" xyz="0 0 0.1625"/>
    <axis xyz="0 0 1"/>
    <limit effort="150.0" lower="-3.141592653589793" upper="3.141592653589793" velocity="3.141592653589793"/>
    <!-- Increase friction in lower joints, they seem to be osscilating alot in sim, and we know friction increases with load -->
    <dynamics damping="0.05" friction="0.3"/>
  </joint>
  <joint name="front_right_shoulder_lift_joint" type="revolute">
    <parent link="front_right_shoulder_link"/>
    <child link="front_right_upper_arm_link"/>
    <origin rpy="1.570796327 0 0" xyz="0 0 0"/>
    <axis xyz="0 0 1"/>
    <limit effort="150.0" lower="-3.141592653589793" upper="3.141592653589793" velocity="3.141592653589793"/>
    <dynamics damping="0.05" friction="0.3"/>
  </joint>
  <joint name="front_right_elbow_joint" type="revolute">
    <parent link="front_right_upper_arm_link"/>
    <child link="front_right_forearm_link"/>
    <origin rpy="0 0 0" xyz="-0.425 0 0"/>
    <axis xyz="0 0 1"/>
    <limit effort="150.0" lower="-3.141592653589793" upper="3.141592653589793" velocity="3.141592653589793"/>
    <dynamics damping="0.05" friction="0.1"/>
  </joint>
  <joint name="front_right_wrist_1_joint" type="revolute">
    <parent link="front_right_forearm_link"/>
    <child link="front_right_wrist_1_link"/>
    <origin rpy="0 0 0" xyz="-0.3922 0 0.1333"/>
    <axis xyz="0 0 1"/>
    <limit effort="28.0" lower="-4.71238898038469" upper="1.5707963267948966" velocity="3.141592653589793"/>
    <dynamics damping="0.05" friction="0.1"/>
  </joint>
  <joint name="front_right_wrist_2_joint" type="revolute">
    <parent link="front_right_wrist_1_link"/>
    <child link="front_right_wrist_2_link"/>
    <origin rpy="1.570796327 0 0" xyz="0 -0.0997 -2.044881182297852e-11"/>
    <axis xyz="0 0 1"/>
    <limit effort="28.0" lower="-4.71238898038469" upper="1.5707963267948966" velocity="3.141592653589793"/>
    <dynamics damping="0.05" friction="0.1"/>
  </joint>
  <joint name="front_right_wrist_3_joint" type="revolute">
    <parent link="front_right_wrist_2_link"/>
    <child link="front_right_wrist_3_link"/>
    <origin rpy="1.570796326589793 3.141592653589793 3.141592653589793" xyz="0 0.0996 -2.042830148012698e-11"/>
    <axis xyz="0 0 1"/>
    <limit effort="28.0" lower="-3.141592653589793" upper="3.141592653589793" velocity="3.141592653589793"/>
    <dynamics damping="0.05" friction="0.1"/>
  </joint>
  <!-- The FT Frame has the same pose as tool0_flip, but we add tool0_flip because its more verbose -->
  <link name="front_right_ft_frame"/>
  <joint name="front_right_wrist_3_link-ft_frame" type="fixed">
    <parent link="front_right_wrist_3_link"/>
    <child link="front_right_ft_frame"/>
    <origin rpy="3.141592653589793 0 0" xyz="0 0 0"/>
  </joint>
  <!-- ROS-Industrial 'base' frame - base_link_ur to UR 'Base' Coordinates transform -->
  <link name="front_right_base"/>
  <joint name="front_right_base_link_ur-base_fixed_joint" type="fixed">
    <!-- Note the rotation over Z of pi radians - as base_link_ur is REP-103
           aligned (i.e., has X+ forward, Y+ left and Z+ up), this is needed
           to correctly align 'base' with the 'Base' coordinate system of
           the UR controller.
      -->
    <origin rpy="0 0 3.141592653589793" xyz="0 0 0"/>
    <parent link="front_right_base_link_ur"/>
    <child link="front_right_base"/>
  </joint>
  <!-- ROS-Industrial 'flange' frame - attachment point for EEF models -->
  <link name="front_right_flange"/>
  <joint name="front_right_wrist_3-flange" type="fixed">
    <parent link="front_right_wrist_3_link"/>
    <child link="front_right_flange"/>
    <origin rpy="0 -1.5707963267948966 -1.5707963267948966" xyz="0 0 0"/>
  </joint>
  <!-- ROS-Industrial 'tool0' frame - all-zeros tool frame -->
  <link name="front_right_tool0"/>
  <joint name="front_right_flange-tool0" type="fixed">
    <!-- default toolframe - X+ left, Y+ up, Z+ front -->
    <origin rpy="1.5707963267948966 0 1.5707963267948966" xyz="0 0 0"/>
    <parent link="front_right_flange"/>
    <child link="front_right_tool0"/>
  </joint>
  <!-- https://github.com/ros-industrial/universal_robot/pull/506/files -->
  <!-- Link from original ur_kinematics, see notes in the ur_ros1 package-->
  <link name="front_right_ee_link"/>
  <joint name="front_right_ee_fixed_joint" type="fixed">
    <parent link="front_right_wrist_3_link"/>
    <child link="front_right_ee_link"/>
    <origin rpy="0.0 -1.5707963267948966 1.5707963267948966" xyz="0 0 0"/>
  </joint>
  <!-- For testing IK offset converions, helpful to have a offset tcp link -->
  <link name="front_right_tcp_world_test"/>
  <joint name="front_right_tool0_to_tcp_world_test" type="fixed">
    <parent link="front_right_tool0"/>
    <child link="front_right_tcp_world_test"/>
    <!-- Go forward a bit along z and flip around -->
    <origin rpy="3.141592653589793 0 0" xyz="0 0 0.1"/>
  </joint>
  <link name="front_right_tool0_flip"/>
  <joint name="front_right_tool0-tool0flip" type="fixed">
    <origin rpy="3.141592653589793 0 0" xyz="0 0 0"/>
    <parent link="front_right_tool0"/>
    <child link="front_right_tool0_flip"/>
  </joint>
  <joint name="front_right_arm_to_hand_mount" type="fixed">
    <origin rpy="0 0 0" xyz="0 0 0"/>
    <parent link="front_right_tool0"/>
    <child link="front_right_robotiq_85_base_link"/>
  </joint>
  <link name="front_right_robotiq_85_base_link">
    <visual>
      <geometry>
        <mesh filename="package://robotiq_description/meshes/visual/2f_85/robotiq_base.dae"/>
      </geometry>
    </visual>
    <collision>
      <geometry>
        <mesh filename="package://robotiq_description/meshes/collision/2f_85/robotiq_base.stl"/>
      </geometry>
    </collision>
    <inertial>
      <origin rpy="0 0 0" xyz="0.0 2.274e-05 0.03232288"/>
      <mass value="6.6320197e-01"/>
      <inertia ixx="5.1617816e-04" ixy="2.936e-8" ixz="0.0" iyy="5.8802208e-04" iyz="-3.2296e-7" izz="3.9462776e-04"/>
    </inertial>
  </link>
  <link name="front_right_robotiq_85_left_knuckle_link">
    <visual>
      <geometry>
        <mesh filename="package://robotiq_description/meshes/visual/2f_85/left_knuckle.dae"/>
      </geometry>
    </visual>
    <collision>
      <geometry>
        <mesh filename="package://robotiq_description/meshes/collision/2f_85/left_knuckle.stl"/>
      </geometry>
    </collision>
    <inertial>
      <origin rpy="0 0 0" xyz="0.01213197 0.0002 -0.00058647"/>
      <mass value="1.384773208e-02"/>
      <inertia ixx="3.5232e-7" ixy="0.0" ixz="1.1744e-7" iyy="2.31944e-6" iyz="0" izz="2.23136e-6"/>
    </inertial>
  </link>
  <link name="front_right_robotiq_85_right_knuckle_link">
    <visual>
      <geometry>
        <mesh filename="package://robotiq_description/meshes/visual/2f_85/right_knuckle.dae"/>
      </geometry>
    </visual>
    <collision>
      <geometry>
        <mesh filename="package://robotiq_description/meshes/collision/2f_85/right_knuckle.stl"/>
      </geometry>
    </collision>
    <inertial>
      <origin rpy="0 0 0" xyz="-0.01213197 0.0002 -0.00058647"/>
      <mass value="1.384773208e-02"/>
      <inertia ixx="3.5232e-7" ixy="0.0" ixz="-1.1744e-7" iyy="2.31944e-6" iyz="0.0" izz="2.23136e-6"/>
    </inertial>
  </link>
  <link name="front_right_robotiq_85_left_finger_link">
    <visual>
      <geometry>
        <mesh filename="package://robotiq_description/meshes/visual/2f_85/left_finger.dae"/>
      </geometry>
    </visual>
    <collision>
      <geometry>
        <mesh filename="package://robotiq_description/meshes/collision/2f_85/left_finger.stl"/>
      </geometry>
    </collision>
    <inertial>
      <origin rpy="0 0 0" xyz="0.00346899 -0.00079447 0.01867121"/>
      <mass value="4.260376752e-02"/>
      <inertia ixx="1.385792000000000e-05" ixy="0.0" ixz="-2.17264e-06" iyy="1.183208e-05" iyz="0.0" izz="5.19672e-06"/>
    </inertial>
  </link>
  <link name="front_right_robotiq_85_right_finger_link">
    <visual>
      <geometry>
        <mesh filename="package://robotiq_description/meshes/visual/2f_85/right_finger.dae"/>
      </geometry>
    </visual>
    <collision>
      <geometry>
        <mesh filename="package://robotiq_description/meshes/collision/2f_85/right_finger.stl"/>
      </geometry>
    </collision>
    <inertial>
      <origin rpy="0 0 0" xyz="-0.00346899 -5.53e-06 0.01867121"/>
      <mass value="4.260376752000000e-02"/>
      <inertia ixx="1.385792e-05" ixy="0.0" ixz="2.17264e-06" iyy="1.183208e-05" iyz="0.0" izz="5.19672e-06"/>
    </inertial>
  </link>
  <link name="front_right_robotiq_85_left_inner_knuckle_link">
    <visual>
      <geometry>
        <mesh filename="package://robotiq_description/meshes/visual/2f_85/left_inner_knuckle.dae"/>
      </geometry>
    </visual>
    <collision>
      <geometry>
        <mesh filename="package://robotiq_description/meshes/collision/2f_85/left_inner_knuckle.stl"/>
      </geometry>
    </collision>
    <inertial>
      <origin rpy="0 0 0" xyz="0.01897699 0.00015001 0.02247101"/>
      <mass value="2.969376448e-02"/>
      <inertia ixx="9.57136e-06" ixy="0.0" ixz="-3.93424e-06" iyy="8.69056e-06" iyz="0.0" izz="8.19144e-06"/>
    </inertial>
  </link>
  <link name="front_right_robotiq_85_right_inner_knuckle_link">
    <visual>
      <geometry>
        <mesh filename="package://robotiq_description/meshes/visual/2f_85/right_inner_knuckle.dae"/>
      </geometry>
    </visual>
    <collision>
      <geometry>
        <mesh filename="package://robotiq_description/meshes/collision/2f_85/right_inner_knuckle.stl"/>
      </geometry>
    </collision>
    <inertial>
      <origin rpy="0 0 0" xyz="-0.01926824 5.001e-05 0.02222178"/>
      <mass value="2.969376448e-02"/>
      <inertia ixx="9.42456e-06" ixy="0.0" ixz="3.9636e-06" iyy="8.69056e-06" iyz="0.0" izz="8.33824e-06"/>
    </inertial>
  </link>
  <link name="front_right_robotiq_85_left_finger_tip_link">
    <visual>
      <geometry>
        <mesh filename="package://robotiq_description/meshes/visual/2f_85/left_finger_tip.dae"/>
      </geometry>
    </visual>
    <collision>
      <geometry>
        <mesh filename="package://robotiq_description/meshes/collision/2f_85/left_finger_tip.stl"/>
      </geometry>
      <surface>
        <friction>
          <ode>
            <mu1>100000.0</mu1>
            <mu2>100000.0</mu2>
          </ode>
        </friction>
        <contact>
          <ode>
            <kp>1e+5</kp>
            <kd>1</kd>
            <soft_cfm>0</soft_cfm>
            <soft_erp>0.2</soft_erp>
            <minDepth>0.002</minDepth>
            <maxVel>0</maxVel>
          </ode>
        </contact>
      </surface>
    </collision>
    <inertial>
      <origin rpy="0 0 0" xyz="-0.01456706 -0.0008 0.01649701"/>
      <mass value="4.268588744e-02"/>
      <inertia ixx="1.048152e-05" ixy="0.0" ixz="3.5232e-6" iyy="1.197888e-05" iyz="0.0" izz="4.22784e-06"/>
    </inertial>
  </link>
  <link name="front_right_robotiq_85_right_finger_tip_link">
    <visual>
      <geometry>
        <mesh filename="package://robotiq_description/meshes/visual/2f_85/right_finger_tip.dae"/>
      </geometry>
    </visual>
    <collision>
      <geometry>
        <mesh filename="package://robotiq_description/meshes/collision/2f_85/right_finger_tip.stl"/>
      </geometry>
      <surface>
        <friction>
          <ode>
            <mu1>100000.0</mu1>
            <mu2>100000.0</mu2>
          </ode>
        </friction>
        <contact>
          <ode>
            <kp>1e+5</kp>
            <kd>1</kd>
            <soft_cfm>0</soft_cfm>
            <soft_erp>0.2</soft_erp>
            <minDepth>0.002</minDepth>
            <maxVel>0</maxVel>
          </ode>
        </contact>
      </surface>
    </collision>
    <inertial>
      <origin rpy="0 0 0" xyz="0.01456706 5e-05 0.01649701"/>
      <mass value="4.268588744e-02"/>
      <inertia ixx="1.048152e-05" ixy="0.0" ixz="-3.5232e-06" iyy="1.197888e-05" iyz="0.0" izz="4.22784e-06"/>
    </inertial>
  </link>
  <!-- BUG ZILLA! https://github.com/stack-of-tasks/pinocchio/issues/2753 Alphabetical order screws it up.. -->
  <!-- Previously called, but switch for something higher in alphabetical order: ${prefix}robotiq_85_left_knuckle_joint -->
  <joint name="front_right_finger_joint" type="revolute">
    <parent link="front_right_robotiq_85_base_link"/>
    <child link="front_right_robotiq_85_left_knuckle_link"/>
    <axis xyz="0 -1 0"/>
    <origin rpy="0 0 0" xyz="0.03060114 0.0 0.05490452"/>
    <limit effort="50" lower="0.0" upper="0.8" velocity="0.5"/>
  </joint>
  <joint name="front_right_robotiq_85_right_knuckle_joint" type="revolute">
    <parent link="front_right_robotiq_85_base_link"/>
    <child link="front_right_robotiq_85_right_knuckle_link"/>
    <axis xyz="0 -1 0"/>
    <origin rpy="0 0 0" xyz="-0.03060114 0.0 0.05490452"/>
    <limit effort="50" lower="-0.8" upper="0.0" velocity="0.5"/>
    <mimic joint="front_right_finger_joint" multiplier="-1" offset="0"/>
  </joint>
  <joint name="front_right_robotiq_85_left_finger_joint" type="fixed">
    <parent link="front_right_robotiq_85_left_knuckle_link"/>
    <child link="front_right_robotiq_85_left_finger_link"/>
    <origin rpy="0 0 0" xyz="0.03152616 0.0 -0.00376347"/>
  </joint>
  <joint name="front_right_robotiq_85_right_finger_joint" type="fixed">
    <parent link="front_right_robotiq_85_right_knuckle_link"/>
    <child link="front_right_robotiq_85_right_finger_link"/>
    <origin rpy="0 0 0" xyz="-0.03152616 0.0 -0.00376347"/>
  </joint>
  <joint name="front_right_robotiq_85_left_inner_knuckle_joint" type="revolute">
    <parent link="front_right_robotiq_85_base_link"/>
    <child link="front_right_robotiq_85_left_inner_knuckle_link"/>
    <axis xyz="0 -1 0"/>
    <origin rpy="0 0 0" xyz="0.0127 0.0 0.06142"/>
    <mimic joint="front_right_finger_joint" multiplier="1" offset="0"/>
    <limit effort="50" lower="-6.283185307179586" upper="6.283185307179586" velocity="0.5"/>
  </joint>
  <joint name="front_right_robotiq_85_right_inner_knuckle_joint" type="revolute">
    <parent link="front_right_robotiq_85_base_link"/>
    <child link="front_right_robotiq_85_right_inner_knuckle_link"/>
    <axis xyz="0 -1 0"/>
    <origin rpy="0 0 0" xyz="-0.0127 0.0 0.06142"/>
    <mimic joint="front_right_finger_joint" multiplier="-1" offset="0"/>
    <limit effort="50" lower="-6.283185307179586" upper="6.283185307179586" velocity="0.5"/>
  </joint>
  <joint name="front_right_robotiq_85_left_finger_tip_joint" type="revolute">
    <parent link="front_right_robotiq_85_left_finger_link"/>
    <child link="front_right_robotiq_85_left_finger_tip_link"/>
    <axis xyz="0 -1 0"/>
    <origin rpy="0 0 0" xyz="0.00563134 0.0 0.04718515"/>
    <mimic joint="front_right_finger_joint" multiplier="-1" offset="0"/>
    <limit effort="50" lower="-6.283185307179586" upper="6.283185307179586" velocity="0.5"/>
  </joint>
  <joint name="front_right_robotiq_85_right_finger_tip_joint" type="revolute">
    <parent link="front_right_robotiq_85_right_finger_link"/>
    <child link="front_right_robotiq_85_right_finger_tip_link"/>
    <axis xyz="0 -1 0"/>
    <origin rpy="0 0 0" xyz="-0.00563134 0.0 0.04718515"/>
    <mimic joint="front_right_finger_joint" multiplier="1" offset="0"/>
    <limit effort="50" lower="-6.283185307179586" upper="6.283185307179586" velocity="0.5"/>
  </joint>
  <!-- End of macro 1 -->
  <!-- Start of macro 2: ArmRobotDescription (type=) -->
<!--
    Generic macro to compose an arm macro and a hand macro.

    Assumptions:
    - The arm macro accepts at least: prefix
    - The hand macro accepts at least: parent, prefix
    - The hand macro will attach its base to the provided parent link

    Notes:
    - Use xacro:call for dynamic macro names.
    - Include files are passed in as absolute paths so they can live in different packages.
  -->
  <!-- links -  main serial chain -->
  <!-- base_link_ur serves as the root of the robot's kinematic tree. It follows REP-103
        conventions (i.e., X+ forward, Y+ left, Z+ up).
        Since some kinematic solvers forbid having inertia values attached to a root link, we've
        added the base_link_inertia link that carries the visual, collision and inertia
        information.
    -->
  <!-- Rename base_link to base_link_ur so you can add another base_link_ur outside... -->
  <link name="back_left_base_link_ur"/>
  <link name="back_left_base_link_inertia">
    <visual>
      <origin rpy="0.0 0.0 3.141592653589793" xyz="0.0 0.0 0.0"/>
      <geometry>
        <mesh filename="package://ur_description/meshes/ur5e/visual/base.dae"/>
      </geometry>
    </visual>
    <collision>
      <origin rpy="0.0 0.0 3.141592653589793" xyz="0.0 0.0 0.0"/>
      <geometry>
        <mesh filename="package://ur_description/meshes/ur5e/collision/base.stl"/>
      </geometry>
    </collision>
    <inertial>
      <mass value="4.0"/>
      <origin rpy="0 0 0" xyz="0 0 0"/>
      <inertia ixx="0.00443333156" ixy="0.0" ixz="0.0" iyy="0.00443333156" iyz="0.0" izz="0.0072"/>
    </inertial>
  </link>
  <link name="back_left_shoulder_link">
    <visual>
      <origin rpy="0.0 0.0 3.141592653589793" xyz="0.0 0.0 0.0"/>
      <geometry>
        <mesh filename="package://ur_description/meshes/ur5e/visual/shoulder.dae"/>
      </geometry>
    </visual>
    <collision>
      <origin rpy="0.0 0.0 3.141592653589793" xyz="0.0 0.0 0.0"/>
      <geometry>
        <mesh filename="package://ur_description/meshes/ur5e/collision/shoulder.stl"/>
      </geometry>
    </collision>
    <inertial>
      <mass value="3.761"/>
      <origin rpy="1.570796326794897 0 0" xyz="0.0 -0.00193 -0.02561"/>
      <inertia ixx="0.0070021" ixy="7.3e-07" ixz="-1.053e-05" iyy="0.00648091" iyz="0.00049994" izz="0.00657286"/>
    </inertial>
  </link>
  <link name="back_left_upper_arm_link">
    <visual>
      <origin rpy="1.5707963267948966 0.0 -1.5707963267948966" xyz="0.0 0.0 0.138"/>
      <geometry>
        <mesh filename="package://ur_description/meshes/ur5e/visual/upperarm.dae"/>
      </geometry>
    </visual>
    <collision>
      <origin rpy="1.5707963267948966 0.0 -1.5707963267948966" xyz="0.0 0.0 0.138"/>
      <geometry>
        <mesh filename="package://ur_description/meshes/ur5e/collision/upperarm.stl"/>
      </geometry>
    </collision>
    <inertial>
      <mass value="8.058"/>
      <origin rpy="0 0 0" xyz="-0.2125 0.0 0.11336"/>
      <inertia ixx="0.01505885" ixy="-5.4e-05" ixz="5.63e-06" iyy="0.33388086" iyz="-1.81e-06" izz="0.33247207"/>
    </inertial>
  </link>
  <link name="back_left_forearm_link">
    <visual>
      <origin rpy="1.5707963267948966 0.0 -1.5707963267948966" xyz="0.0 0.0 0.007"/>
      <geometry>
        <mesh filename="package://ur_description/meshes/ur5e/visual/forearm.dae"/>
      </geometry>
    </visual>
    <collision>
      <origin rpy="1.5707963267948966 0.0 -1.5707963267948966" xyz="0.0 0.0 0.007"/>
      <geometry>
        <mesh filename="package://ur_description/meshes/ur5e/collision/forearm.stl"/>
      </geometry>
    </collision>
    <inertial>
      <mass value="2.846"/>
      <origin rpy="0 0 0" xyz="-0.2422 0.0 0.0265"/>
      <inertia ixx="0.00399632" ixy="-1.365e-05" ixz="0.00137272" iyy="0.07879254" iyz="-6.6e-06" izz="0.0784851"/>
    </inertial>
  </link>
  <link name="back_left_wrist_1_link">
    <visual>
      <origin rpy="1.5707963267948966 0.0 0.0" xyz="0.0 0.0 -0.127"/>
      <geometry>
        <mesh filename="package://ur_description/meshes/ur5e/visual/wrist1.dae"/>
      </geometry>
    </visual>
    <collision>
      <origin rpy="1.5707963267948966 0.0 0.0" xyz="0.0 0.0 -0.127"/>
      <geometry>
        <mesh filename="package://ur_description/meshes/ur5e/collision/wrist1.stl"/>
      </geometry>
    </collision>
    <inertial>
      <mass value="1.37"/>
      <origin rpy="1.570796326794897 0 0" xyz="0.0 -0.01634 -0.0018"/>
      <inertia ixx="0.00165491" ixy="-2.82e-06" ixz="-4.38e-06" iyy="0.00135962" iyz="0.00010157" izz="0.00126279"/>
    </inertial>
  </link>
  <link name="back_left_wrist_2_link">
    <visual>
      <origin rpy="0.0 0.0 0.0" xyz="0.0 0.0 -0.0997"/>
      <geometry>
        <mesh filename="package://ur_description/meshes/ur5e/visual/wrist2.dae"/>
      </geometry>
    </visual>
    <collision>
      <origin rpy="0.0 0.0 0.0" xyz="0.0 0.0 -0.0997"/>
      <geometry>
        <mesh filename="package://ur_description/meshes/ur5e/collision/wrist2.stl"/>
      </geometry>
    </collision>
    <inertial>
      <mass value="1.3"/>
      <origin rpy="-1.570796326794897 0 0" xyz="0.0 0.01634 -0.0018"/>
      <inertia ixx="0.00135617" ixy="-2.74e-06" ixz="4.44e-06" iyy="0.00127827" iyz="-5.048e-05" izz="0.00096614"/>
    </inertial>
  </link>
  <link name="back_left_wrist_3_link">
    <visual>
      <origin rpy="1.5707963267948966 0.0 0.0" xyz="0.0 0.0 -0.0989"/>
      <geometry>
        <mesh filename="package://ur_description/meshes/ur5e/visual/wrist3.dae"/>
      </geometry>
    </visual>
    <collision>
      <origin rpy="1.5707963267948966 0.0 0.0" xyz="0.0 0.0 -0.0989"/>
      <geometry>
        <mesh filename="package://ur_description/meshes/ur5e/collision/wrist3.stl"/>
      </geometry>
    </collision>
    <inertial>
      <mass value="0.365"/>
      <origin rpy="0 0 0" xyz="0.0 0.0 -0.001159"/>
      <inertia ixx="0.00018694" ixy="6e-08" ixz="-1.7e-07" iyy="0.00018908" iyz="-9.2e-07" izz="0.00025756"/>
    </inertial>
  </link>
  <!-- base_joint fixes base_link_ur to the environment -->
  <!-- <joint name="${tf_prefix}base_joint" type="fixed">
      <xacro:insert_block name="origin" />
      <parent link="${parent}" />
      <child link="${tf_prefix}base_link_ur" />
    </joint> -->
  <!-- joints - main serial chain -->
  <joint name="back_left_base_link_ur-base_link_inertia" type="fixed">
    <parent link="back_left_base_link_ur"/>
    <child link="back_left_base_link_inertia"/>
    <!-- 'base_link_ur' is REP-103 aligned (so X+ forward), while the internal
           frames of the robot/controller have X+ pointing backwards.
           Use the joint between 'base_link_ur' and 'base_link_inertia' (a dummy
           link/frame) to introduce the necessary rotation over Z (of pi rad).
      -->
    <origin rpy="0 0 3.141592653589793" xyz="0 0 0"/>
  </joint>
  <joint name="back_left_shoulder_pan_joint" type="revolute">
    <parent link="back_left_base_link_inertia"/>
    <child link="back_left_shoulder_link"/>
    <origin rpy="0 0 0" xyz="0 0 0.1625"/>
    <axis xyz="0 0 1"/>
    <limit effort="150.0" lower="-3.141592653589793" upper="3.141592653589793" velocity="3.141592653589793"/>
    <!-- Increase friction in lower joints, they seem to be osscilating alot in sim, and we know friction increases with load -->
    <dynamics damping="0.05" friction="0.3"/>
  </joint>
  <joint name="back_left_shoulder_lift_joint" type="revolute">
    <parent link="back_left_shoulder_link"/>
    <child link="back_left_upper_arm_link"/>
    <origin rpy="1.570796327 0 0" xyz="0 0 0"/>
    <axis xyz="0 0 1"/>
    <limit effort="150.0" lower="-3.141592653589793" upper="3.141592653589793" velocity="3.141592653589793"/>
    <dynamics damping="0.05" friction="0.3"/>
  </joint>
  <joint name="back_left_elbow_joint" type="revolute">
    <parent link="back_left_upper_arm_link"/>
    <child link="back_left_forearm_link"/>
    <origin rpy="0 0 0" xyz="-0.425 0 0"/>
    <axis xyz="0 0 1"/>
    <limit effort="150.0" lower="-3.141592653589793" upper="3.141592653589793" velocity="3.141592653589793"/>
    <dynamics damping="0.05" friction="0.1"/>
  </joint>
  <joint name="back_left_wrist_1_joint" type="revolute">
    <parent link="back_left_forearm_link"/>
    <child link="back_left_wrist_1_link"/>
    <origin rpy="0 0 0" xyz="-0.3922 0 0.1333"/>
    <axis xyz="0 0 1"/>
    <limit effort="28.0" lower="-4.71238898038469" upper="1.5707963267948966" velocity="3.141592653589793"/>
    <dynamics damping="0.05" friction="0.1"/>
  </joint>
  <joint name="back_left_wrist_2_joint" type="revolute">
    <parent link="back_left_wrist_1_link"/>
    <child link="back_left_wrist_2_link"/>
    <origin rpy="1.570796327 0 0" xyz="0 -0.0997 -2.044881182297852e-11"/>
    <axis xyz="0 0 1"/>
    <limit effort="28.0" lower="-4.71238898038469" upper="1.5707963267948966" velocity="3.141592653589793"/>
    <dynamics damping="0.05" friction="0.1"/>
  </joint>
  <joint name="back_left_wrist_3_joint" type="revolute">
    <parent link="back_left_wrist_2_link"/>
    <child link="back_left_wrist_3_link"/>
    <origin rpy="1.570796326589793 3.141592653589793 3.141592653589793" xyz="0 0.0996 -2.042830148012698e-11"/>
    <axis xyz="0 0 1"/>
    <limit effort="28.0" lower="-3.141592653589793" upper="3.141592653589793" velocity="3.141592653589793"/>
    <dynamics damping="0.05" friction="0.1"/>
  </joint>
  <!-- The FT Frame has the same pose as tool0_flip, but we add tool0_flip because its more verbose -->
  <link name="back_left_ft_frame"/>
  <joint name="back_left_wrist_3_link-ft_frame" type="fixed">
    <parent link="back_left_wrist_3_link"/>
    <child link="back_left_ft_frame"/>
    <origin rpy="3.141592653589793 0 0" xyz="0 0 0"/>
  </joint>
  <!-- ROS-Industrial 'base' frame - base_link_ur to UR 'Base' Coordinates transform -->
  <link name="back_left_base"/>
  <joint name="back_left_base_link_ur-base_fixed_joint" type="fixed">
    <!-- Note the rotation over Z of pi radians - as base_link_ur is REP-103
           aligned (i.e., has X+ forward, Y+ left and Z+ up), this is needed
           to correctly align 'base' with the 'Base' coordinate system of
           the UR controller.
      -->
    <origin rpy="0 0 3.141592653589793" xyz="0 0 0"/>
    <parent link="back_left_base_link_ur"/>
    <child link="back_left_base"/>
  </joint>
  <!-- ROS-Industrial 'flange' frame - attachment point for EEF models -->
  <link name="back_left_flange"/>
  <joint name="back_left_wrist_3-flange" type="fixed">
    <parent link="back_left_wrist_3_link"/>
    <child link="back_left_flange"/>
    <origin rpy="0 -1.5707963267948966 -1.5707963267948966" xyz="0 0 0"/>
  </joint>
  <!-- ROS-Industrial 'tool0' frame - all-zeros tool frame -->
  <link name="back_left_tool0"/>
  <joint name="back_left_flange-tool0" type="fixed">
    <!-- default toolframe - X+ left, Y+ up, Z+ front -->
    <origin rpy="1.5707963267948966 0 1.5707963267948966" xyz="0 0 0"/>
    <parent link="back_left_flange"/>
    <child link="back_left_tool0"/>
  </joint>
  <!-- https://github.com/ros-industrial/universal_robot/pull/506/files -->
  <!-- Link from original ur_kinematics, see notes in the ur_ros1 package-->
  <link name="back_left_ee_link"/>
  <joint name="back_left_ee_fixed_joint" type="fixed">
    <parent link="back_left_wrist_3_link"/>
    <child link="back_left_ee_link"/>
    <origin rpy="0.0 -1.5707963267948966 1.5707963267948966" xyz="0 0 0"/>
  </joint>
  <!-- For testing IK offset converions, helpful to have a offset tcp link -->
  <link name="back_left_tcp_world_test"/>
  <joint name="back_left_tool0_to_tcp_world_test" type="fixed">
    <parent link="back_left_tool0"/>
    <child link="back_left_tcp_world_test"/>
    <!-- Go forward a bit along z and flip around -->
    <origin rpy="3.141592653589793 0 0" xyz="0 0 0.1"/>
  </joint>
  <link name="back_left_tool0_flip"/>
  <joint name="back_left_tool0-tool0flip" type="fixed">
    <origin rpy="3.141592653589793 0 0" xyz="0 0 0"/>
    <parent link="back_left_tool0"/>
    <child link="back_left_tool0_flip"/>
  </joint>
  <joint name="back_left_arm_to_hand_mount" type="fixed">
    <origin rpy="0 0 0" xyz="0 0 0"/>
    <parent link="back_left_tool0"/>
    <child link="back_left_robotiq_85_base_link"/>
  </joint>
  <link name="back_left_robotiq_85_base_link">
    <visual>
      <geometry>
        <mesh filename="package://robotiq_description/meshes/visual/2f_85/robotiq_base.dae"/>
      </geometry>
    </visual>
    <collision>
      <geometry>
        <mesh filename="package://robotiq_description/meshes/collision/2f_85/robotiq_base.stl"/>
      </geometry>
    </collision>
    <inertial>
      <origin rpy="0 0 0" xyz="0.0 2.274e-05 0.03232288"/>
      <mass value="6.6320197e-01"/>
      <inertia ixx="5.1617816e-04" ixy="2.936e-8" ixz="0.0" iyy="5.8802208e-04" iyz="-3.2296e-7" izz="3.9462776e-04"/>
    </inertial>
  </link>
  <link name="back_left_robotiq_85_left_knuckle_link">
    <visual>
      <geometry>
        <mesh filename="package://robotiq_description/meshes/visual/2f_85/left_knuckle.dae"/>
      </geometry>
    </visual>
    <collision>
      <geometry>
        <mesh filename="package://robotiq_description/meshes/collision/2f_85/left_knuckle.stl"/>
      </geometry>
    </collision>
    <inertial>
      <origin rpy="0 0 0" xyz="0.01213197 0.0002 -0.00058647"/>
      <mass value="1.384773208e-02"/>
      <inertia ixx="3.5232e-7" ixy="0.0" ixz="1.1744e-7" iyy="2.31944e-6" iyz="0" izz="2.23136e-6"/>
    </inertial>
  </link>
  <link name="back_left_robotiq_85_right_knuckle_link">
    <visual>
      <geometry>
        <mesh filename="package://robotiq_description/meshes/visual/2f_85/right_knuckle.dae"/>
      </geometry>
    </visual>
    <collision>
      <geometry>
        <mesh filename="package://robotiq_description/meshes/collision/2f_85/right_knuckle.stl"/>
      </geometry>
    </collision>
    <inertial>
      <origin rpy="0 0 0" xyz="-0.01213197 0.0002 -0.00058647"/>
      <mass value="1.384773208e-02"/>
      <inertia ixx="3.5232e-7" ixy="0.0" ixz="-1.1744e-7" iyy="2.31944e-6" iyz="0.0" izz="2.23136e-6"/>
    </inertial>
  </link>
  <link name="back_left_robotiq_85_left_finger_link">
    <visual>
      <geometry>
        <mesh filename="package://robotiq_description/meshes/visual/2f_85/left_finger.dae"/>
      </geometry>
    </visual>
    <collision>
      <geometry>
        <mesh filename="package://robotiq_description/meshes/collision/2f_85/left_finger.stl"/>
      </geometry>
    </collision>
    <inertial>
      <origin rpy="0 0 0" xyz="0.00346899 -0.00079447 0.01867121"/>
      <mass value="4.260376752e-02"/>
      <inertia ixx="1.385792000000000e-05" ixy="0.0" ixz="-2.17264e-06" iyy="1.183208e-05" iyz="0.0" izz="5.19672e-06"/>
    </inertial>
  </link>
  <link name="back_left_robotiq_85_right_finger_link">
    <visual>
      <geometry>
        <mesh filename="package://robotiq_description/meshes/visual/2f_85/right_finger.dae"/>
      </geometry>
    </visual>
    <collision>
      <geometry>
        <mesh filename="package://robotiq_description/meshes/collision/2f_85/right_finger.stl"/>
      </geometry>
    </collision>
    <inertial>
      <origin rpy="0 0 0" xyz="-0.00346899 -5.53e-06 0.01867121"/>
      <mass value="4.260376752000000e-02"/>
      <inertia ixx="1.385792e-05" ixy="0.0" ixz="2.17264e-06" iyy="1.183208e-05" iyz="0.0" izz="5.19672e-06"/>
    </inertial>
  </link>
  <link name="back_left_robotiq_85_left_inner_knuckle_link">
    <visual>
      <geometry>
        <mesh filename="package://robotiq_description/meshes/visual/2f_85/left_inner_knuckle.dae"/>
      </geometry>
    </visual>
    <collision>
      <geometry>
        <mesh filename="package://robotiq_description/meshes/collision/2f_85/left_inner_knuckle.stl"/>
      </geometry>
    </collision>
    <inertial>
      <origin rpy="0 0 0" xyz="0.01897699 0.00015001 0.02247101"/>
      <mass value="2.969376448e-02"/>
      <inertia ixx="9.57136e-06" ixy="0.0" ixz="-3.93424e-06" iyy="8.69056e-06" iyz="0.0" izz="8.19144e-06"/>
    </inertial>
  </link>
  <link name="back_left_robotiq_85_right_inner_knuckle_link">
    <visual>
      <geometry>
        <mesh filename="package://robotiq_description/meshes/visual/2f_85/right_inner_knuckle.dae"/>
      </geometry>
    </visual>
    <collision>
      <geometry>
        <mesh filename="package://robotiq_description/meshes/collision/2f_85/right_inner_knuckle.stl"/>
      </geometry>
    </collision>
    <inertial>
      <origin rpy="0 0 0" xyz="-0.01926824 5.001e-05 0.02222178"/>
      <mass value="2.969376448e-02"/>
      <inertia ixx="9.42456e-06" ixy="0.0" ixz="3.9636e-06" iyy="8.69056e-06" iyz="0.0" izz="8.33824e-06"/>
    </inertial>
  </link>
  <link name="back_left_robotiq_85_left_finger_tip_link">
    <visual>
      <geometry>
        <mesh filename="package://robotiq_description/meshes/visual/2f_85/left_finger_tip.dae"/>
      </geometry>
    </visual>
    <collision>
      <geometry>
        <mesh filename="package://robotiq_description/meshes/collision/2f_85/left_finger_tip.stl"/>
      </geometry>
      <surface>
        <friction>
          <ode>
            <mu1>100000.0</mu1>
            <mu2>100000.0</mu2>
          </ode>
        </friction>
        <contact>
          <ode>
            <kp>1e+5</kp>
            <kd>1</kd>
            <soft_cfm>0</soft_cfm>
            <soft_erp>0.2</soft_erp>
            <minDepth>0.002</minDepth>
            <maxVel>0</maxVel>
          </ode>
        </contact>
      </surface>
    </collision>
    <inertial>
      <origin rpy="0 0 0" xyz="-0.01456706 -0.0008 0.01649701"/>
      <mass value="4.268588744e-02"/>
      <inertia ixx="1.048152e-05" ixy="0.0" ixz="3.5232e-6" iyy="1.197888e-05" iyz="0.0" izz="4.22784e-06"/>
    </inertial>
  </link>
  <link name="back_left_robotiq_85_right_finger_tip_link">
    <visual>
      <geometry>
        <mesh filename="package://robotiq_description/meshes/visual/2f_85/right_finger_tip.dae"/>
      </geometry>
    </visual>
    <collision>
      <geometry>
        <mesh filename="package://robotiq_description/meshes/collision/2f_85/right_finger_tip.stl"/>
      </geometry>
      <surface>
        <friction>
          <ode>
            <mu1>100000.0</mu1>
            <mu2>100000.0</mu2>
          </ode>
        </friction>
        <contact>
          <ode>
            <kp>1e+5</kp>
            <kd>1</kd>
            <soft_cfm>0</soft_cfm>
            <soft_erp>0.2</soft_erp>
            <minDepth>0.002</minDepth>
            <maxVel>0</maxVel>
          </ode>
        </contact>
      </surface>
    </collision>
    <inertial>
      <origin rpy="0 0 0" xyz="0.01456706 5e-05 0.01649701"/>
      <mass value="4.268588744e-02"/>
      <inertia ixx="1.048152e-05" ixy="0.0" ixz="-3.5232e-06" iyy="1.197888e-05" iyz="0.0" izz="4.22784e-06"/>
    </inertial>
  </link>
  <!-- BUG ZILLA! https://github.com/stack-of-tasks/pinocchio/issues/2753 Alphabetical order screws it up.. -->
  <!-- Previously called, but switch for something higher in alphabetical order: ${prefix}robotiq_85_left_knuckle_joint -->
  <joint name="back_left_finger_joint" type="revolute">
    <parent link="back_left_robotiq_85_base_link"/>
    <child link="back_left_robotiq_85_left_knuckle_link"/>
    <axis xyz="0 -1 0"/>
    <origin rpy="0 0 0" xyz="0.03060114 0.0 0.05490452"/>
    <limit effort="50" lower="0.0" upper="0.8" velocity="0.5"/>
  </joint>
  <joint name="back_left_robotiq_85_right_knuckle_joint" type="revolute">
    <parent link="back_left_robotiq_85_base_link"/>
    <child link="back_left_robotiq_85_right_knuckle_link"/>
    <axis xyz="0 -1 0"/>
    <origin rpy="0 0 0" xyz="-0.03060114 0.0 0.05490452"/>
    <limit effort="50" lower="-0.8" upper="0.0" velocity="0.5"/>
    <mimic joint="back_left_finger_joint" multiplier="-1" offset="0"/>
  </joint>
  <joint name="back_left_robotiq_85_left_finger_joint" type="fixed">
    <parent link="back_left_robotiq_85_left_knuckle_link"/>
    <child link="back_left_robotiq_85_left_finger_link"/>
    <origin rpy="0 0 0" xyz="0.03152616 0.0 -0.00376347"/>
  </joint>
  <joint name="back_left_robotiq_85_right_finger_joint" type="fixed">
    <parent link="back_left_robotiq_85_right_knuckle_link"/>
    <child link="back_left_robotiq_85_right_finger_link"/>
    <origin rpy="0 0 0" xyz="-0.03152616 0.0 -0.00376347"/>
  </joint>
  <joint name="back_left_robotiq_85_left_inner_knuckle_joint" type="revolute">
    <parent link="back_left_robotiq_85_base_link"/>
    <child link="back_left_robotiq_85_left_inner_knuckle_link"/>
    <axis xyz="0 -1 0"/>
    <origin rpy="0 0 0" xyz="0.0127 0.0 0.06142"/>
    <mimic joint="back_left_finger_joint" multiplier="1" offset="0"/>
    <limit effort="50" lower="-6.283185307179586" upper="6.283185307179586" velocity="0.5"/>
  </joint>
  <joint name="back_left_robotiq_85_right_inner_knuckle_joint" type="revolute">
    <parent link="back_left_robotiq_85_base_link"/>
    <child link="back_left_robotiq_85_right_inner_knuckle_link"/>
    <axis xyz="0 -1 0"/>
    <origin rpy="0 0 0" xyz="-0.0127 0.0 0.06142"/>
    <mimic joint="back_left_finger_joint" multiplier="-1" offset="0"/>
    <limit effort="50" lower="-6.283185307179586" upper="6.283185307179586" velocity="0.5"/>
  </joint>
  <joint name="back_left_robotiq_85_left_finger_tip_joint" type="revolute">
    <parent link="back_left_robotiq_85_left_finger_link"/>
    <child link="back_left_robotiq_85_left_finger_tip_link"/>
    <axis xyz="0 -1 0"/>
    <origin rpy="0 0 0" xyz="0.00563134 0.0 0.04718515"/>
    <mimic joint="back_left_finger_joint" multiplier="-1" offset="0"/>
    <limit effort="50" lower="-6.283185307179586" upper="6.283185307179586" velocity="0.5"/>
  </joint>
  <joint name="back_left_robotiq_85_right_finger_tip_joint" type="revolute">
    <parent link="back_left_robotiq_85_right_finger_link"/>
    <child link="back_left_robotiq_85_right_finger_tip_link"/>
    <axis xyz="0 -1 0"/>
    <origin rpy="0 0 0" xyz="-0.00563134 0.0 0.04718515"/>
    <mimic joint="back_left_finger_joint" multiplier="1" offset="0"/>
    <limit effort="50" lower="-6.283185307179586" upper="6.283185307179586" velocity="0.5"/>
  </joint>
  <!-- End of macro 2 -->
  <!-- Start of macro 3: ArmRobotDescription (type=) -->
<!--
    Generic macro to compose an arm macro and a hand macro.

    Assumptions:
    - The arm macro accepts at least: prefix
    - The hand macro accepts at least: parent, prefix
    - The hand macro will attach its base to the provided parent link

    Notes:
    - Use xacro:call for dynamic macro names.
    - Include files are passed in as absolute paths so they can live in different packages.
  -->
  <!-- links -  main serial chain -->
  <!-- base_link_ur serves as the root of the robot's kinematic tree. It follows REP-103
        conventions (i.e., X+ forward, Y+ left, Z+ up).
        Since some kinematic solvers forbid having inertia values attached to a root link, we've
        added the base_link_inertia link that carries the visual, collision and inertia
        information.
    -->
  <!-- Rename base_link to base_link_ur so you can add another base_link_ur outside... -->
  <link name="back_right_base_link_ur"/>
  <link name="back_right_base_link_inertia">
    <visual>
      <origin rpy="0.0 0.0 3.141592653589793" xyz="0.0 0.0 0.0"/>
      <geometry>
        <mesh filename="package://ur_description/meshes/ur5e/visual/base.dae"/>
      </geometry>
    </visual>
    <collision>
      <origin rpy="0.0 0.0 3.141592653589793" xyz="0.0 0.0 0.0"/>
      <geometry>
        <mesh filename="package://ur_description/meshes/ur5e/collision/base.stl"/>
      </geometry>
    </collision>
    <inertial>
      <mass value="4.0"/>
      <origin rpy="0 0 0" xyz="0 0 0"/>
      <inertia ixx="0.00443333156" ixy="0.0" ixz="0.0" iyy="0.00443333156" iyz="0.0" izz="0.0072"/>
    </inertial>
  </link>
  <link name="back_right_shoulder_link">
    <visual>
      <origin rpy="0.0 0.0 3.141592653589793" xyz="0.0 0.0 0.0"/>
      <geometry>
        <mesh filename="package://ur_description/meshes/ur5e/visual/shoulder.dae"/>
      </geometry>
    </visual>
    <collision>
      <origin rpy="0.0 0.0 3.141592653589793" xyz="0.0 0.0 0.0"/>
      <geometry>
        <mesh filename="package://ur_description/meshes/ur5e/collision/shoulder.stl"/>
      </geometry>
    </collision>
    <inertial>
      <mass value="3.761"/>
      <origin rpy="1.570796326794897 0 0" xyz="0.0 -0.00193 -0.02561"/>
      <inertia ixx="0.0070021" ixy="7.3e-07" ixz="-1.053e-05" iyy="0.00648091" iyz="0.00049994" izz="0.00657286"/>
    </inertial>
  </link>
  <link name="back_right_upper_arm_link">
    <visual>
      <origin rpy="1.5707963267948966 0.0 -1.5707963267948966" xyz="0.0 0.0 0.138"/>
      <geometry>
        <mesh filename="package://ur_description/meshes/ur5e/visual/upperarm.dae"/>
      </geometry>
    </visual>
    <collision>
      <origin rpy="1.5707963267948966 0.0 -1.5707963267948966" xyz="0.0 0.0 0.138"/>
      <geometry>
        <mesh filename="package://ur_description/meshes/ur5e/collision/upperarm.stl"/>
      </geometry>
    </collision>
    <inertial>
      <mass value="8.058"/>
      <origin rpy="0 0 0" xyz="-0.2125 0.0 0.11336"/>
      <inertia ixx="0.01505885" ixy="-5.4e-05" ixz="5.63e-06" iyy="0.33388086" iyz="-1.81e-06" izz="0.33247207"/>
    </inertial>
  </link>
  <link name="back_right_forearm_link">
    <visual>
      <origin rpy="1.5707963267948966 0.0 -1.5707963267948966" xyz="0.0 0.0 0.007"/>
      <geometry>
        <mesh filename="package://ur_description/meshes/ur5e/visual/forearm.dae"/>
      </geometry>
    </visual>
    <collision>
      <origin rpy="1.5707963267948966 0.0 -1.5707963267948966" xyz="0.0 0.0 0.007"/>
      <geometry>
        <mesh filename="package://ur_description/meshes/ur5e/collision/forearm.stl"/>
      </geometry>
    </collision>
    <inertial>
      <mass value="2.846"/>
      <origin rpy="0 0 0" xyz="-0.2422 0.0 0.0265"/>
      <inertia ixx="0.00399632" ixy="-1.365e-05" ixz="0.00137272" iyy="0.07879254" iyz="-6.6e-06" izz="0.0784851"/>
    </inertial>
  </link>
  <link name="back_right_wrist_1_link">
    <visual>
      <origin rpy="1.5707963267948966 0.0 0.0" xyz="0.0 0.0 -0.127"/>
      <geometry>
        <mesh filename="package://ur_description/meshes/ur5e/visual/wrist1.dae"/>
      </geometry>
    </visual>
    <collision>
      <origin rpy="1.5707963267948966 0.0 0.0" xyz="0.0 0.0 -0.127"/>
      <geometry>
        <mesh filename="package://ur_description/meshes/ur5e/collision/wrist1.stl"/>
      </geometry>
    </collision>
    <inertial>
      <mass value="1.37"/>
      <origin rpy="1.570796326794897 0 0" xyz="0.0 -0.01634 -0.0018"/>
      <inertia ixx="0.00165491" ixy="-2.82e-06" ixz="-4.38e-06" iyy="0.00135962" iyz="0.00010157" izz="0.00126279"/>
    </inertial>
  </link>
  <link name="back_right_wrist_2_link">
    <visual>
      <origin rpy="0.0 0.0 0.0" xyz="0.0 0.0 -0.0997"/>
      <geometry>
        <mesh filename="package://ur_description/meshes/ur5e/visual/wrist2.dae"/>
      </geometry>
    </visual>
    <collision>
      <origin rpy="0.0 0.0 0.0" xyz="0.0 0.0 -0.0997"/>
      <geometry>
        <mesh filename="package://ur_description/meshes/ur5e/collision/wrist2.stl"/>
      </geometry>
    </collision>
    <inertial>
      <mass value="1.3"/>
      <origin rpy="-1.570796326794897 0 0" xyz="0.0 0.01634 -0.0018"/>
      <inertia ixx="0.00135617" ixy="-2.74e-06" ixz="4.44e-06" iyy="0.00127827" iyz="-5.048e-05" izz="0.00096614"/>
    </inertial>
  </link>
  <link name="back_right_wrist_3_link">
    <visual>
      <origin rpy="1.5707963267948966 0.0 0.0" xyz="0.0 0.0 -0.0989"/>
      <geometry>
        <mesh filename="package://ur_description/meshes/ur5e/visual/wrist3.dae"/>
      </geometry>
    </visual>
    <collision>
      <origin rpy="1.5707963267948966 0.0 0.0" xyz="0.0 0.0 -0.0989"/>
      <geometry>
        <mesh filename="package://ur_description/meshes/ur5e/collision/wrist3.stl"/>
      </geometry>
    </collision>
    <inertial>
      <mass value="0.365"/>
      <origin rpy="0 0 0" xyz="0.0 0.0 -0.001159"/>
      <inertia ixx="0.00018694" ixy="6e-08" ixz="-1.7e-07" iyy="0.00018908" iyz="-9.2e-07" izz="0.00025756"/>
    </inertial>
  </link>
  <!-- base_joint fixes base_link_ur to the environment -->
  <!-- <joint name="${tf_prefix}base_joint" type="fixed">
      <xacro:insert_block name="origin" />
      <parent link="${parent}" />
      <child link="${tf_prefix}base_link_ur" />
    </joint> -->
  <!-- joints - main serial chain -->
  <joint name="back_right_base_link_ur-base_link_inertia" type="fixed">
    <parent link="back_right_base_link_ur"/>
    <child link="back_right_base_link_inertia"/>
    <!-- 'base_link_ur' is REP-103 aligned (so X+ forward), while the internal
           frames of the robot/controller have X+ pointing backwards.
           Use the joint between 'base_link_ur' and 'base_link_inertia' (a dummy
           link/frame) to introduce the necessary rotation over Z (of pi rad).
      -->
    <origin rpy="0 0 3.141592653589793" xyz="0 0 0"/>
  </joint>
  <joint name="back_right_shoulder_pan_joint" type="revolute">
    <parent link="back_right_base_link_inertia"/>
    <child link="back_right_shoulder_link"/>
    <origin rpy="0 0 0" xyz="0 0 0.1625"/>
    <axis xyz="0 0 1"/>
    <limit effort="150.0" lower="-3.141592653589793" upper="3.141592653589793" velocity="3.141592653589793"/>
    <!-- Increase friction in lower joints, they seem to be osscilating alot in sim, and we know friction increases with load -->
    <dynamics damping="0.05" friction="0.3"/>
  </joint>
  <joint name="back_right_shoulder_lift_joint" type="revolute">
    <parent link="back_right_shoulder_link"/>
    <child link="back_right_upper_arm_link"/>
    <origin rpy="1.570796327 0 0" xyz="0 0 0"/>
    <axis xyz="0 0 1"/>
    <limit effort="150.0" lower="-3.141592653589793" upper="3.141592653589793" velocity="3.141592653589793"/>
    <dynamics damping="0.05" friction="0.3"/>
  </joint>
  <joint name="back_right_elbow_joint" type="revolute">
    <parent link="back_right_upper_arm_link"/>
    <child link="back_right_forearm_link"/>
    <origin rpy="0 0 0" xyz="-0.425 0 0"/>
    <axis xyz="0 0 1"/>
    <limit effort="150.0" lower="-3.141592653589793" upper="3.141592653589793" velocity="3.141592653589793"/>
    <dynamics damping="0.05" friction="0.1"/>
  </joint>
  <joint name="back_right_wrist_1_joint" type="revolute">
    <parent link="back_right_forearm_link"/>
    <child link="back_right_wrist_1_link"/>
    <origin rpy="0 0 0" xyz="-0.3922 0 0.1333"/>
    <axis xyz="0 0 1"/>
    <limit effort="28.0" lower="-4.71238898038469" upper="1.5707963267948966" velocity="3.141592653589793"/>
    <dynamics damping="0.05" friction="0.1"/>
  </joint>
  <joint name="back_right_wrist_2_joint" type="revolute">
    <parent link="back_right_wrist_1_link"/>
    <child link="back_right_wrist_2_link"/>
    <origin rpy="1.570796327 0 0" xyz="0 -0.0997 -2.044881182297852e-11"/>
    <axis xyz="0 0 1"/>
    <limit effort="28.0" lower="-4.71238898038469" upper="1.5707963267948966" velocity="3.141592653589793"/>
    <dynamics damping="0.05" friction="0.1"/>
  </joint>
  <joint name="back_right_wrist_3_joint" type="revolute">
    <parent link="back_right_wrist_2_link"/>
    <child link="back_right_wrist_3_link"/>
    <origin rpy="1.570796326589793 3.141592653589793 3.141592653589793" xyz="0 0.0996 -2.042830148012698e-11"/>
    <axis xyz="0 0 1"/>
    <limit effort="28.0" lower="-3.141592653589793" upper="3.141592653589793" velocity="3.141592653589793"/>
    <dynamics damping="0.05" friction="0.1"/>
  </joint>
  <!-- The FT Frame has the same pose as tool0_flip, but we add tool0_flip because its more verbose -->
  <link name="back_right_ft_frame"/>
  <joint name="back_right_wrist_3_link-ft_frame" type="fixed">
    <parent link="back_right_wrist_3_link"/>
    <child link="back_right_ft_frame"/>
    <origin rpy="3.141592653589793 0 0" xyz="0 0 0"/>
  </joint>
  <!-- ROS-Industrial 'base' frame - base_link_ur to UR 'Base' Coordinates transform -->
  <link name="back_right_base"/>
  <joint name="back_right_base_link_ur-base_fixed_joint" type="fixed">
    <!-- Note the rotation over Z of pi radians - as base_link_ur is REP-103
           aligned (i.e., has X+ forward, Y+ left and Z+ up), this is needed
           to correctly align 'base' with the 'Base' coordinate system of
           the UR controller.
      -->
    <origin rpy="0 0 3.141592653589793" xyz="0 0 0"/>
    <parent link="back_right_base_link_ur"/>
    <child link="back_right_base"/>
  </joint>
  <!-- ROS-Industrial 'flange' frame - attachment point for EEF models -->
  <link name="back_right_flange"/>
  <joint name="back_right_wrist_3-flange" type="fixed">
    <parent link="back_right_wrist_3_link"/>
    <child link="back_right_flange"/>
    <origin rpy="0 -1.5707963267948966 -1.5707963267948966" xyz="0 0 0"/>
  </joint>
  <!-- ROS-Industrial 'tool0' frame - all-zeros tool frame -->
  <link name="back_right_tool0"/>
  <joint name="back_right_flange-tool0" type="fixed">
    <!-- default toolframe - X+ left, Y+ up, Z+ front -->
    <origin rpy="1.5707963267948966 0 1.5707963267948966" xyz="0 0 0"/>
    <parent link="back_right_flange"/>
    <child link="back_right_tool0"/>
  </joint>
  <!-- https://github.com/ros-industrial/universal_robot/pull/506/files -->
  <!-- Link from original ur_kinematics, see notes in the ur_ros1 package-->
  <link name="back_right_ee_link"/>
  <joint name="back_right_ee_fixed_joint" type="fixed">
    <parent link="back_right_wrist_3_link"/>
    <child link="back_right_ee_link"/>
    <origin rpy="0.0 -1.5707963267948966 1.5707963267948966" xyz="0 0 0"/>
  </joint>
  <!-- For testing IK offset converions, helpful to have a offset tcp link -->
  <link name="back_right_tcp_world_test"/>
  <joint name="back_right_tool0_to_tcp_world_test" type="fixed">
    <parent link="back_right_tool0"/>
    <child link="back_right_tcp_world_test"/>
    <!-- Go forward a bit along z and flip around -->
    <origin rpy="3.141592653589793 0 0" xyz="0 0 0.1"/>
  </joint>
  <link name="back_right_tool0_flip"/>
  <joint name="back_right_tool0-tool0flip" type="fixed">
    <origin rpy="3.141592653589793 0 0" xyz="0 0 0"/>
    <parent link="back_right_tool0"/>
    <child link="back_right_tool0_flip"/>
  </joint>
  <joint name="back_right_arm_to_hand_mount" type="fixed">
    <origin rpy="0 0 0" xyz="0 0 0"/>
    <parent link="back_right_tool0"/>
    <child link="back_right_robotiq_85_base_link"/>
  </joint>
  <link name="back_right_robotiq_85_base_link">
    <visual>
      <geometry>
        <mesh filename="package://robotiq_description/meshes/visual/2f_85/robotiq_base.dae"/>
      </geometry>
    </visual>
    <collision>
      <geometry>
        <mesh filename="package://robotiq_description/meshes/collision/2f_85/robotiq_base.stl"/>
      </geometry>
    </collision>
    <inertial>
      <origin rpy="0 0 0" xyz="0.0 2.274e-05 0.03232288"/>
      <mass value="6.6320197e-01"/>
      <inertia ixx="5.1617816e-04" ixy="2.936e-8" ixz="0.0" iyy="5.8802208e-04" iyz="-3.2296e-7" izz="3.9462776e-04"/>
    </inertial>
  </link>
  <link name="back_right_robotiq_85_left_knuckle_link">
    <visual>
      <geometry>
        <mesh filename="package://robotiq_description/meshes/visual/2f_85/left_knuckle.dae"/>
      </geometry>
    </visual>
    <collision>
      <geometry>
        <mesh filename="package://robotiq_description/meshes/collision/2f_85/left_knuckle.stl"/>
      </geometry>
    </collision>
    <inertial>
      <origin rpy="0 0 0" xyz="0.01213197 0.0002 -0.00058647"/>
      <mass value="1.384773208e-02"/>
      <inertia ixx="3.5232e-7" ixy="0.0" ixz="1.1744e-7" iyy="2.31944e-6" iyz="0" izz="2.23136e-6"/>
    </inertial>
  </link>
  <link name="back_right_robotiq_85_right_knuckle_link">
    <visual>
      <geometry>
        <mesh filename="package://robotiq_description/meshes/visual/2f_85/right_knuckle.dae"/>
      </geometry>
    </visual>
    <collision>
      <geometry>
        <mesh filename="package://robotiq_description/meshes/collision/2f_85/right_knuckle.stl"/>
      </geometry>
    </collision>
    <inertial>
      <origin rpy="0 0 0" xyz="-0.01213197 0.0002 -0.00058647"/>
      <mass value="1.384773208e-02"/>
      <inertia ixx="3.5232e-7" ixy="0.0" ixz="-1.1744e-7" iyy="2.31944e-6" iyz="0.0" izz="2.23136e-6"/>
    </inertial>
  </link>
  <link name="back_right_robotiq_85_left_finger_link">
    <visual>
      <geometry>
        <mesh filename="package://robotiq_description/meshes/visual/2f_85/left_finger.dae"/>
      </geometry>
    </visual>
    <collision>
      <geometry>
        <mesh filename="package://robotiq_description/meshes/collision/2f_85/left_finger.stl"/>
      </geometry>
    </collision>
    <inertial>
      <origin rpy="0 0 0" xyz="0.00346899 -0.00079447 0.01867121"/>
      <mass value="4.260376752e-02"/>
      <inertia ixx="1.385792000000000e-05" ixy="0.0" ixz="-2.17264e-06" iyy="1.183208e-05" iyz="0.0" izz="5.19672e-06"/>
    </inertial>
  </link>
  <link name="back_right_robotiq_85_right_finger_link">
    <visual>
      <geometry>
        <mesh filename="package://robotiq_description/meshes/visual/2f_85/right_finger.dae"/>
      </geometry>
    </visual>
    <collision>
      <geometry>
        <mesh filename="package://robotiq_description/meshes/collision/2f_85/right_finger.stl"/>
      </geometry>
    </collision>
    <inertial>
      <origin rpy="0 0 0" xyz="-0.00346899 -5.53e-06 0.01867121"/>
      <mass value="4.260376752000000e-02"/>
      <inertia ixx="1.385792e-05" ixy="0.0" ixz="2.17264e-06" iyy="1.183208e-05" iyz="0.0" izz="5.19672e-06"/>
    </inertial>
  </link>
  <link name="back_right_robotiq_85_left_inner_knuckle_link">
    <visual>
      <geometry>
        <mesh filename="package://robotiq_description/meshes/visual/2f_85/left_inner_knuckle.dae"/>
      </geometry>
    </visual>
    <collision>
      <geometry>
        <mesh filename="package://robotiq_description/meshes/collision/2f_85/left_inner_knuckle.stl"/>
      </geometry>
    </collision>
    <inertial>
      <origin rpy="0 0 0" xyz="0.01897699 0.00015001 0.02247101"/>
      <mass value="2.969376448e-02"/>
      <inertia ixx="9.57136e-06" ixy="0.0" ixz="-3.93424e-06" iyy="8.69056e-06" iyz="0.0" izz="8.19144e-06"/>
    </inertial>
  </link>
  <link name="back_right_robotiq_85_right_inner_knuckle_link">
    <visual>
      <geometry>
        <mesh filename="package://robotiq_description/meshes/visual/2f_85/right_inner_knuckle.dae"/>
      </geometry>
    </visual>
    <collision>
      <geometry>
        <mesh filename="package://robotiq_description/meshes/collision/2f_85/right_inner_knuckle.stl"/>
      </geometry>
    </collision>
    <inertial>
      <origin rpy="0 0 0" xyz="-0.01926824 5.001e-05 0.02222178"/>
      <mass value="2.969376448e-02"/>
      <inertia ixx="9.42456e-06" ixy="0.0" ixz="3.9636e-06" iyy="8.69056e-06" iyz="0.0" izz="8.33824e-06"/>
    </inertial>
  </link>
  <link name="back_right_robotiq_85_left_finger_tip_link">
    <visual>
      <geometry>
        <mesh filename="package://robotiq_description/meshes/visual/2f_85/left_finger_tip.dae"/>
      </geometry>
    </visual>
    <collision>
      <geometry>
        <mesh filename="package://robotiq_description/meshes/collision/2f_85/left_finger_tip.stl"/>
      </geometry>
      <surface>
        <friction>
          <ode>
            <mu1>100000.0</mu1>
            <mu2>100000.0</mu2>
          </ode>
        </friction>
        <contact>
          <ode>
            <kp>1e+5</kp>
            <kd>1</kd>
            <soft_cfm>0</soft_cfm>
            <soft_erp>0.2</soft_erp>
            <minDepth>0.002</minDepth>
            <maxVel>0</maxVel>
          </ode>
        </contact>
      </surface>
    </collision>
    <inertial>
      <origin rpy="0 0 0" xyz="-0.01456706 -0.0008 0.01649701"/>
      <mass value="4.268588744e-02"/>
      <inertia ixx="1.048152e-05" ixy="0.0" ixz="3.5232e-6" iyy="1.197888e-05" iyz="0.0" izz="4.22784e-06"/>
    </inertial>
  </link>
  <link name="back_right_robotiq_85_right_finger_tip_link">
    <visual>
      <geometry>
        <mesh filename="package://robotiq_description/meshes/visual/2f_85/right_finger_tip.dae"/>
      </geometry>
    </visual>
    <collision>
      <geometry>
        <mesh filename="package://robotiq_description/meshes/collision/2f_85/right_finger_tip.stl"/>
      </geometry>
      <surface>
        <friction>
          <ode>
            <mu1>100000.0</mu1>
            <mu2>100000.0</mu2>
          </ode>
        </friction>
        <contact>
          <ode>
            <kp>1e+5</kp>
            <kd>1</kd>
            <soft_cfm>0</soft_cfm>
            <soft_erp>0.2</soft_erp>
            <minDepth>0.002</minDepth>
            <maxVel>0</maxVel>
          </ode>
        </contact>
      </surface>
    </collision>
    <inertial>
      <origin rpy="0 0 0" xyz="0.01456706 5e-05 0.01649701"/>
      <mass value="4.268588744e-02"/>
      <inertia ixx="1.048152e-05" ixy="0.0" ixz="-3.5232e-06" iyy="1.197888e-05" iyz="0.0" izz="4.22784e-06"/>
    </inertial>
  </link>
  <!-- BUG ZILLA! https://github.com/stack-of-tasks/pinocchio/issues/2753 Alphabetical order screws it up.. -->
  <!-- Previously called, but switch for something higher in alphabetical order: ${prefix}robotiq_85_left_knuckle_joint -->
  <joint name="back_right_finger_joint" type="revolute">
    <parent link="back_right_robotiq_85_base_link"/>
    <child link="back_right_robotiq_85_left_knuckle_link"/>
    <axis xyz="0 -1 0"/>
    <origin rpy="0 0 0" xyz="0.03060114 0.0 0.05490452"/>
    <limit effort="50" lower="0.0" upper="0.8" velocity="0.5"/>
  </joint>
  <joint name="back_right_robotiq_85_right_knuckle_joint" type="revolute">
    <parent link="back_right_robotiq_85_base_link"/>
    <child link="back_right_robotiq_85_right_knuckle_link"/>
    <axis xyz="0 -1 0"/>
    <origin rpy="0 0 0" xyz="-0.03060114 0.0 0.05490452"/>
    <limit effort="50" lower="-0.8" upper="0.0" velocity="0.5"/>
    <mimic joint="back_right_finger_joint" multiplier="-1" offset="0"/>
  </joint>
  <joint name="back_right_robotiq_85_left_finger_joint" type="fixed">
    <parent link="back_right_robotiq_85_left_knuckle_link"/>
    <child link="back_right_robotiq_85_left_finger_link"/>
    <origin rpy="0 0 0" xyz="0.03152616 0.0 -0.00376347"/>
  </joint>
  <joint name="back_right_robotiq_85_right_finger_joint" type="fixed">
    <parent link="back_right_robotiq_85_right_knuckle_link"/>
    <child link="back_right_robotiq_85_right_finger_link"/>
    <origin rpy="0 0 0" xyz="-0.03152616 0.0 -0.00376347"/>
  </joint>
  <joint name="back_right_robotiq_85_left_inner_knuckle_joint" type="revolute">
    <parent link="back_right_robotiq_85_base_link"/>
    <child link="back_right_robotiq_85_left_inner_knuckle_link"/>
    <axis xyz="0 -1 0"/>
    <origin rpy="0 0 0" xyz="0.0127 0.0 0.06142"/>
    <mimic joint="back_right_finger_joint" multiplier="1" offset="0"/>
    <limit effort="50" lower="-6.283185307179586" upper="6.283185307179586" velocity="0.5"/>
  </joint>
  <joint name="back_right_robotiq_85_right_inner_knuckle_joint" type="revolute">
    <parent link="back_right_robotiq_85_base_link"/>
    <child link="back_right_robotiq_85_right_inner_knuckle_link"/>
    <axis xyz="0 -1 0"/>
    <origin rpy="0 0 0" xyz="-0.0127 0.0 0.06142"/>
    <mimic joint="back_right_finger_joint" multiplier="-1" offset="0"/>
    <limit effort="50" lower="-6.283185307179586" upper="6.283185307179586" velocity="0.5"/>
  </joint>
  <joint name="back_right_robotiq_85_left_finger_tip_joint" type="revolute">
    <parent link="back_right_robotiq_85_left_finger_link"/>
    <child link="back_right_robotiq_85_left_finger_tip_link"/>
    <axis xyz="0 -1 0"/>
    <origin rpy="0 0 0" xyz="0.00563134 0.0 0.04718515"/>
    <mimic joint="back_right_finger_joint" multiplier="-1" offset="0"/>
    <limit effort="50" lower="-6.283185307179586" upper="6.283185307179586" velocity="0.5"/>
  </joint>
  <joint name="back_right_robotiq_85_right_finger_tip_joint" type="revolute">
    <parent link="back_right_robotiq_85_right_finger_link"/>
    <child link="back_right_robotiq_85_right_finger_tip_link"/>
    <axis xyz="0 -1 0"/>
    <origin rpy="0 0 0" xyz="-0.00563134 0.0 0.04718515"/>
    <mimic joint="back_right_finger_joint" multiplier="1" offset="0"/>
    <limit effort="50" lower="-6.283185307179586" upper="6.283185307179586" velocity="0.5"/>
  </joint>
  <!-- End of macro 3 -->
  <!-- Custom links (added directly to URDF) -->
    <link name="world"/> 

    <link name="base_link"/> 


  <!-- Custom joints (added directly to URDF) -->
    <joint name="world_joint" type="fixed">
    <origin xyz="0.000000 0.000000 0.000000" rpy="0.000000 -0.000000 0.000000"/>
    <parent link="world"/>
    <child link="base_link"/>
  </joint>

    <joint name="front_left_joint" type="fixed">
    <origin xyz="0.000000 0.000000 0.000000" rpy="0.000000 -0.000000 0.000000"/>
    <parent link="base_link"/>
    <child link="front_left_base_link_ur"/>
  </joint>

    <joint name="front_right_joint" type="fixed">
    <origin xyz="0.000000 0.000000 0.000000" rpy="0.000000 -0.000000 0.000000"/>
    <parent link="base_link"/>
    <child link="front_right_base_link_ur"/>
  </joint>

    <joint name="back_left_joint" type="fixed">
    <origin xyz="0.000000 0.000000 0.000000" rpy="0.000000 -0.000000 0.000000"/>
    <parent link="base_link"/>
    <child link="back_left_base_link_ur"/>
  </joint>

    <joint name="back_right_joint" type="fixed">
    <origin xyz="0.000000 0.000000 0.000000" rpy="0.000000 -0.000000 0.000000"/>
    <parent link="base_link"/>
    <child link="back_right_base_link_ur"/>
  </joint>



</robot>
