<?xml version="1.0" ?>
<robot name="composite">
  <!-- Auto-generated Composite Config URDF -->
  <material name="StoglRobotics/Violet">
    <color rgba="0.4 0.1803921568627451 0.5686274509803921 1.0"/>
    <ambient>1 0 0 1</ambient>
    <diffuse>1 0 0 1</diffuse>
    <specular>0.1 0.1 0.1 1</specular>
    <emissive>0 0 0 0</emissive>
  </material>
  <material name="StoglRobotics/DarkGrey">
    <color rgba="0.2 0.2 0.2 1.0"/>
    <ambient>1 0 0 1</ambient>
    <diffuse>1 0 0 1</diffuse>
    <specular>0.1 0.1 0.1 1</specular>
    <emissive>0 0 0 0</emissive>
  </material>
  <material name="StoglRobotics/LightGrey">
    <color rgba="0.7607843137254902 0.7607843137254902 0.7607843137254902 1.0"/>
    <ambient>1 0 0 1</ambient>
    <diffuse>1 0 0 1</diffuse>
    <specular>0.1 0.1 0.1 1</specular>
    <emissive>0 0 0 0</emissive>
  </material>
  <material name="Ghost">
    <color rgba="0.7607843137254902 0.7607843137254902 0.7607843137254902 0.5"/>
    <ambient>1 0 0 1</ambient>
    <diffuse>1 0 0 1</diffuse>
    <specular>0.1 0.1 0.1 1</specular>
    <emissive>0 0 0 0</emissive>
  </material>
  <material name="Black">
    <color rgba="0.0 0.0 0.0 1"/>
    <ambient>1 0 0 1</ambient>
    <diffuse>1 0 0 1</diffuse>
    <specular>0.1 0.1 0.1 1</specular>
    <emissive>0 0 0 0</emissive>
  </material>
  <material name="White">
    <color rgba="1.0 1.0 1.0 1"/>
    <ambient>1 0 0 1</ambient>
    <diffuse>1 0 0 1</diffuse>
    <specular>0.1 0.1 0.1 1</specular>
    <emissive>0 0 0 0</emissive>
  </material>
  <material name="Red">
    <color rgba="1.0 0.0 0.0 1.0"/>
    <ambient>1 0 0 1</ambient>
    <diffuse>1 0 0 1</diffuse>
    <specular>0.1 0.1 0.1 1</specular>
    <emissive>0 0 0 0</emissive>
  </material>
  <material name="Orange">
    <color rgba="1.0 0.55 0.0 1.0"/>
    <ambient>1 0.5 0 1</ambient>
    <diffuse>1 0.5 0 1</diffuse>
    <specular>0.1 0.1 0.1 1</specular>
    <emissive>0 0 0 0</emissive>
  </material>
  <material name="Yellow">
    <color rgba="1.0 1.0 0.0 1.0"/>
    <ambient>1 1 0 1</ambient>
    <diffuse>1 1 0 1</diffuse>
    <specular>0.1 0.1 0.1 1</specular>
    <emissive>0 0 0 0</emissive>
  </material>
  <material name="Green">
    <color rgba="0.0 1.0 0.0 1.0"/>
    <ambient>0 1 0 1</ambient>
    <diffuse>0 1 0 1</diffuse>
    <specular>0.1 0.1 0.1 1</specular>
    <emissive>0 0 0 0</emissive>
  </material>
  <material name="Blue">
    <color rgba="0.0 0.0 1.0 1.0"/>
    <ambient>0 0 1 1</ambient>
    <diffuse>0 0 1 1</diffuse>
    <specular>0.1 0.1 0.1 1</specular>
    <emissive>0 0 0 0</emissive>
  </material>
  <material name="Indigo">
    <color rgba="0.29 0.0 0.51 1.0"/>
    <ambient>0.25 0 0.45 1</ambient>
    <diffuse>0.25 0 0.45 1</diffuse>
    <specular>0.1 0.1 0.1 1</specular>
    <emissive>0 0 0 0</emissive>
  </material>
  <material name="Violet">
    <color rgba="0.56 0.0 1.0 1.0"/>
    <ambient>0.5 0 1 1</ambient>
    <diffuse>0.5 0 1 1</diffuse>
    <specular>0.1 0.1 0.1 1</specular>
    <emissive>0 0 0 0</emissive>
  </material>
  <!-- Create world link -->
  <link name="world"/>
  <!-- Attach base_link to world -->
  <joint name="world_to_base_link" type="fixed">
    <origin rpy="0 0 0" xyz="0 0 0"/>
    <parent link="world"/>
    <child link="base_link"/>
  </joint>
  <link name="base_link"/>
  <!-- Attach first component's base to base_link -->
  <joint name="base_link_joint" type="fixed">
    <origin rpy="0 0 0" xyz="0 0 0"/>
    <parent link="base_link"/>
    <child link="arm_base_link_ur"/>
  </joint>
  <!--
    Auto-generated Composite Macro
    Generated for: 2 descriptions, 1 mounting joints
  -->
  <!--
    Base UR robot series xacro macro.

    NOTE this is NOT a URDF. It cannot directly be loaded by consumers
    expecting a flattened '.urdf' file. See the top-level '.xacro' for that
    (but note that .xacro must still be processed by the xacro command).

    This file models the base kinematic chain of a UR robot, which then gets
    parameterised by various configuration files to convert it into a UR3(e),
    UR5(e), UR10(e) or UR16e.

    NOTE the default kinematic parameters (i.e., link lengths, frame locations,
    offsets, etc) do not correspond to any particular robot. They are defaults
    only. There WILL be non-zero offsets between the Forward Kinematics results
    in TF (i.e., robot_state_publisher) and the values reported by the Teach
    Pendant.

    For accurate (and robot-specific) transforms, the 'kinematics_parameters_file'
    parameter MUST point to a .yaml file containing the appropriate values for
    the targeted robot.

    If using the UniversalRobots/Universal_Robots_ROS_Driver, follow the steps
    described in the readme of that repository to extract the kinematic
    calibration from the controller and generate the required .yaml file.

    Main author of the migration to yaml configs Ludovic Delval.

    Contributors to previous versions (in no particular order)

     - Denis Stogl
     - Lovro Ivanov
     - Felix Messmer
     - Kelsey Hawkins
     - Wim Meeussen
     - Shaun Edwards
     - Nadia Hammoudeh Garcia
     - Dave Hershberger
     - G. vd. Hoorn
     - Philip Long
     - Dave Coleman
     - Miguel Prada
     - Mathias Luedtke
     - Marcel Schnirring
     - Felix von Drigalski
     - Felix Exner
     - Jimmy Da Silva
     - Ajit Krisshna N L
     - Muhammad Asif Rana
  -->
  <!-- links -  main serial chain -->
  <!-- base_link_ur serves as the root of the robot's kinematic tree. It follows REP-103
        conventions (i.e., X+ forward, Y+ left, Z+ up).
        Since some kinematic solvers forbid having inertia values attached to a root link, we've
        added the base_link_inertia link that carries the visual, collision and inertia
        information.
    -->
  <!-- Rename base_link to base_link_ur so you can add another base_link_ur outside... -->
  <link name="arm_base_link_ur"/>
  <link name="arm_base_link_inertia">
    <visual>
      <origin rpy="0.0 0.0 3.141592653589793" xyz="0.0 0.0 0.0"/>
      <geometry>
        <mesh filename="file:///home/bam/public_ws/install/ur_description/share/ur_description/meshes/ur5e/visual/base.dae"/>
      </geometry>
    </visual>
    <collision>
      <origin rpy="0.0 0.0 3.141592653589793" xyz="0.0 0.0 0.0"/>
      <geometry>
        <mesh filename="file:///home/bam/public_ws/install/ur_description/share/ur_description/meshes/ur5e/collision/base.stl"/>
      </geometry>
    </collision>
    <inertial>
      <mass value="4.0"/>
      <origin rpy="0 0 0" xyz="0 0 0"/>
      <inertia ixx="0.00443333156" ixy="0.0" ixz="0.0" iyy="0.00443333156" iyz="0.0" izz="0.0072"/>
    </inertial>
  </link>
  <link name="arm_shoulder_link">
    <visual>
      <origin rpy="0.0 0.0 3.141592653589793" xyz="0.0 0.0 0.0"/>
      <geometry>
        <mesh filename="file:///home/bam/public_ws/install/ur_description/share/ur_description/meshes/ur5e/visual/shoulder.dae"/>
      </geometry>
    </visual>
    <collision>
      <origin rpy="0.0 0.0 3.141592653589793" xyz="0.0 0.0 0.0"/>
      <geometry>
        <mesh filename="file:///home/bam/public_ws/install/ur_description/share/ur_description/meshes/ur5e/collision/shoulder.stl"/>
      </geometry>
    </collision>
    <inertial>
      <mass value="3.761"/>
      <origin rpy="1.570796326794897 0 0" xyz="0.0 -0.00193 -0.02561"/>
      <inertia ixx="0.0070021" ixy="7.3e-07" ixz="-1.053e-05" iyy="0.00648091" iyz="0.00049994" izz="0.00657286"/>
    </inertial>
  </link>
  <link name="arm_upper_arm_link">
    <visual>
      <origin rpy="1.5707963267948966 0.0 -1.5707963267948966" xyz="0.0 0.0 0.138"/>
      <geometry>
        <mesh filename="file:///home/bam/public_ws/install/ur_description/share/ur_description/meshes/ur5e/visual/upperarm.dae"/>
      </geometry>
    </visual>
    <collision>
      <origin rpy="1.5707963267948966 0.0 -1.5707963267948966" xyz="0.0 0.0 0.138"/>
      <geometry>
        <mesh filename="file:///home/bam/public_ws/install/ur_description/share/ur_description/meshes/ur5e/collision/upperarm.stl"/>
      </geometry>
    </collision>
    <inertial>
      <mass value="8.058"/>
      <origin rpy="0 0 0" xyz="-0.2125 0.0 0.11336"/>
      <inertia ixx="0.01505885" ixy="-5.4e-05" ixz="5.63e-06" iyy="0.33388086" iyz="-1.81e-06" izz="0.33247207"/>
    </inertial>
  </link>
  <link name="arm_forearm_link">
    <visual>
      <origin rpy="1.5707963267948966 0.0 -1.5707963267948966" xyz="0.0 0.0 0.007"/>
      <geometry>
        <mesh filename="file:///home/bam/public_ws/install/ur_description/share/ur_description/meshes/ur5e/visual/forearm.dae"/>
      </geometry>
    </visual>
    <collision>
      <origin rpy="1.5707963267948966 0.0 -1.5707963267948966" xyz="0.0 0.0 0.007"/>
      <geometry>
        <mesh filename="file:///home/bam/public_ws/install/ur_description/share/ur_description/meshes/ur5e/collision/forearm.stl"/>
      </geometry>
    </collision>
    <inertial>
      <mass value="2.846"/>
      <origin rpy="0 0 0" xyz="-0.2422 0.0 0.0265"/>
      <inertia ixx="0.00399632" ixy="-1.365e-05" ixz="0.00137272" iyy="0.07879254" iyz="-6.6e-06" izz="0.0784851"/>
    </inertial>
  </link>
  <link name="arm_wrist_1_link">
    <visual>
      <origin rpy="1.5707963267948966 0.0 0.0" xyz="0.0 0.0 -0.127"/>
      <geometry>
        <mesh filename="file:///home/bam/public_ws/install/ur_description/share/ur_description/meshes/ur5e/visual/wrist1.dae"/>
      </geometry>
    </visual>
    <collision>
      <origin rpy="1.5707963267948966 0.0 0.0" xyz="0.0 0.0 -0.127"/>
      <geometry>
        <mesh filename="file:///home/bam/public_ws/install/ur_description/share/ur_description/meshes/ur5e/collision/wrist1.stl"/>
      </geometry>
    </collision>
    <inertial>
      <mass value="1.37"/>
      <origin rpy="1.570796326794897 0 0" xyz="0.0 -0.01634 -0.0018"/>
      <inertia ixx="0.00165491" ixy="-2.82e-06" ixz="-4.38e-06" iyy="0.00135962" iyz="0.00010157" izz="0.00126279"/>
    </inertial>
  </link>
  <link name="arm_wrist_2_link">
    <visual>
      <origin rpy="0.0 0.0 0.0" xyz="0.0 0.0 -0.0997"/>
      <geometry>
        <mesh filename="file:///home/bam/public_ws/install/ur_description/share/ur_description/meshes/ur5e/visual/wrist2.dae"/>
      </geometry>
    </visual>
    <collision>
      <origin rpy="0.0 0.0 0.0" xyz="0.0 0.0 -0.0997"/>
      <geometry>
        <mesh filename="file:///home/bam/public_ws/install/ur_description/share/ur_description/meshes/ur5e/collision/wrist2.stl"/>
      </geometry>
    </collision>
    <inertial>
      <mass value="1.3"/>
      <origin rpy="-1.570796326794897 0 0" xyz="0.0 0.01634 -0.0018"/>
      <inertia ixx="0.00135617" ixy="-2.74e-06" ixz="4.44e-06" iyy="0.00127827" iyz="-5.048e-05" izz="0.00096614"/>
    </inertial>
  </link>
  <link name="arm_wrist_3_link">
    <visual>
      <origin rpy="1.5707963267948966 0.0 0.0" xyz="0.0 0.0 -0.0989"/>
      <geometry>
        <mesh filename="file:///home/bam/public_ws/install/ur_description/share/ur_description/meshes/ur5e/visual/wrist3.dae"/>
      </geometry>
    </visual>
    <collision>
      <origin rpy="1.5707963267948966 0.0 0.0" xyz="0.0 0.0 -0.0989"/>
      <geometry>
        <mesh filename="file:///home/bam/public_ws/install/ur_description/share/ur_description/meshes/ur5e/collision/wrist3.stl"/>
      </geometry>
    </collision>
    <inertial>
      <mass value="0.365"/>
      <origin rpy="0 0 0" xyz="0.0 0.0 -0.001159"/>
      <inertia ixx="0.00018694" ixy="6e-08" ixz="-1.7e-07" iyy="0.00018908" iyz="-9.2e-07" izz="0.00025756"/>
    </inertial>
  </link>
  <!-- base_joint fixes base_link_ur to the environment -->
  <!-- <joint name="${tf_prefix}base_joint" type="fixed">
      <xacro:insert_block name="origin" />
      <parent link="${parent}" />
      <child link="${tf_prefix}base_link_ur" />
    </joint> -->
  <!-- joints - main serial chain -->
  <joint name="arm_base_link_ur-base_link_inertia" type="fixed">
    <parent link="arm_base_link_ur"/>
    <child link="arm_base_link_inertia"/>
    <!-- 'base_link_ur' is REP-103 aligned (so X+ forward), while the internal
           frames of the robot/controller have X+ pointing backwards.
           Use the joint between 'base_link_ur' and 'base_link_inertia' (a dummy
           link/frame) to introduce the necessary rotation over Z (of pi rad).
      -->
    <origin rpy="0 0 3.141592653589793" xyz="0 0 0"/>
  </joint>
  <joint name="arm_shoulder_pan_joint" type="revolute">
    <parent link="arm_base_link_inertia"/>
    <child link="arm_shoulder_link"/>
    <origin rpy="0 0 0" xyz="0 0 0.1625"/>
    <axis xyz="0 0 1"/>
    <limit effort="150.0" lower="-3.141592653589793" upper="3.141592653589793" velocity="3.141592653589793"/>
    <!-- Increase friction in lower joints, they seem to be osscilating alot in sim, and we know friction increases with load -->
    <dynamics damping="0.05" friction="0.3"/>
  </joint>
  <joint name="arm_shoulder_lift_joint" type="revolute">
    <parent link="arm_shoulder_link"/>
    <child link="arm_upper_arm_link"/>
    <origin rpy="1.570796327 0 0" xyz="0 0 0"/>
    <axis xyz="0 0 1"/>
    <limit effort="150.0" lower="-3.141592653589793" upper="3.141592653589793" velocity="3.141592653589793"/>
    <dynamics damping="0.05" friction="0.3"/>
  </joint>
  <joint name="arm_elbow_joint" type="revolute">
    <parent link="arm_upper_arm_link"/>
    <child link="arm_forearm_link"/>
    <origin rpy="0 0 0" xyz="-0.425 0 0"/>
    <axis xyz="0 0 1"/>
    <limit effort="150.0" lower="-3.141592653589793" upper="3.141592653589793" velocity="3.141592653589793"/>
    <dynamics damping="0.05" friction="0.1"/>
  </joint>
  <joint name="arm_wrist_1_joint" type="revolute">
    <parent link="arm_forearm_link"/>
    <child link="arm_wrist_1_link"/>
    <origin rpy="0 0 0" xyz="-0.3922 0 0.1333"/>
    <axis xyz="0 0 1"/>
    <limit effort="28.0" lower="-4.71238898038469" upper="1.5707963267948966" velocity="3.141592653589793"/>
    <dynamics damping="0.05" friction="0.1"/>
  </joint>
  <joint name="arm_wrist_2_joint" type="revolute">
    <parent link="arm_wrist_1_link"/>
    <child link="arm_wrist_2_link"/>
    <origin rpy="1.570796327 0 0" xyz="0 -0.0997 -2.044881182297852e-11"/>
    <axis xyz="0 0 1"/>
    <limit effort="28.0" lower="-4.71238898038469" upper="1.5707963267948966" velocity="3.141592653589793"/>
    <dynamics damping="0.05" friction="0.1"/>
  </joint>
  <joint name="arm_wrist_3_joint" type="revolute">
    <parent link="arm_wrist_2_link"/>
    <child link="arm_wrist_3_link"/>
    <origin rpy="1.570796326589793 3.141592653589793 3.141592653589793" xyz="0 0.0996 -2.042830148012698e-11"/>
    <axis xyz="0 0 1"/>
    <limit effort="28.0" lower="-3.141592653589793" upper="3.141592653589793" velocity="3.141592653589793"/>
    <dynamics damping="0.05" friction="0.1"/>
  </joint>
  <!-- The FT Frame has the same pose as tool0_flip, but we add tool0_flip because its more verbose -->
  <link name="arm_ft_frame"/>
  <joint name="arm_wrist_3_link-ft_frame" type="fixed">
    <parent link="arm_wrist_3_link"/>
    <child link="arm_ft_frame"/>
    <origin rpy="3.141592653589793 0 0" xyz="0 0 0"/>
  </joint>
  <!-- ROS-Industrial 'base' frame - base_link_ur to UR 'Base' Coordinates transform -->
  <link name="arm_base"/>
  <joint name="arm_base_link_ur-base_fixed_joint" type="fixed">
    <!-- Note the rotation over Z of pi radians - as base_link_ur is REP-103
           aligned (i.e., has X+ forward, Y+ left and Z+ up), this is needed
           to correctly align 'base' with the 'Base' coordinate system of
           the UR controller.
      -->
    <origin rpy="0 0 3.141592653589793" xyz="0 0 0"/>
    <parent link="arm_base_link_ur"/>
    <child link="arm_base"/>
  </joint>
  <!-- ROS-Industrial 'flange' frame - attachment point for EEF models -->
  <link name="arm_flange"/>
  <joint name="arm_wrist_3-flange" type="fixed">
    <parent link="arm_wrist_3_link"/>
    <child link="arm_flange"/>
    <origin rpy="0 -1.5707963267948966 -1.5707963267948966" xyz="0 0 0"/>
  </joint>
  <!-- ROS-Industrial 'tool0' frame - all-zeros tool frame -->
  <link name="arm_tool0"/>
  <joint name="arm_flange-tool0" type="fixed">
    <!-- default toolframe - X+ left, Y+ up, Z+ front -->
    <origin rpy="1.5707963267948966 0 1.5707963267948966" xyz="0 0 0"/>
    <parent link="arm_flange"/>
    <child link="arm_tool0"/>
  </joint>
  <!-- https://github.com/ros-industrial/universal_robot/pull/506/files -->
  <!-- Link from original ur_kinematics, see notes in the ur_ros1 package-->
  <link name="arm_ee_link"/>
  <joint name="arm_ee_fixed_joint" type="fixed">
    <parent link="arm_wrist_3_link"/>
    <child link="arm_ee_link"/>
    <origin rpy="0.0 -1.5707963267948966 1.5707963267948966" xyz="0 0 0"/>
  </joint>
  <!-- For testing IK offset converions, helpful to have a offset tcp link -->
  <link name="arm_tcp_world_test"/>
  <joint name="arm_tool0_to_tcp_world_test" type="fixed">
    <parent link="arm_tool0"/>
    <child link="arm_tcp_world_test"/>
    <!-- Go forward a bit along z and flip around -->
    <origin rpy="3.141592653589793 0 0" xyz="0 0 0.1"/>
  </joint>
  <link name="arm_tool0_flip"/>
  <joint name="arm_tool0-tool0flip" type="fixed">
    <origin rpy="3.141592653589793 0 0" xyz="0 0 0"/>
    <parent link="arm_tool0"/>
    <child link="arm_tool0_flip"/>
  </joint>
  <link name="hand_eef_link_1">
    <visual>
      <origin rpy="0 0 0" xyz="0 0 0"/>
      <geometry>
        <mesh filename="file:///home/bam/bam_ws/src/bam_common/bam_descriptions/urdf/crab_claw_v1/meshes/hand.stl"/>
      </geometry>
      <material name="StoglRobotics/LightGrey"/>
    </visual>
    <!-- For collision inspiration see other gazebo grippers -->
    <collision>
      <origin rpy="0 0 0" xyz="0 0 0"/>
      <geometry>
        <mesh filename="file:///home/bam/bam_ws/src/bam_common/bam_descriptions/urdf/crab_claw_v1/meshes/fixed_finger.stl"/>
      </geometry>
    </collision>
    <!-- <collision>
                <origin xyz="0 0 ${0.06/2}" rpy="0 0 0"/>
                <geometry>
                    <box size="0.05 0.06 0.06"/>
                </geometry>
            </collision> -->
    <inertial>
      <origin xyz="-0.000055 0.002094 0.039905"/>
      <mass value="0.273365"/>
      <inertia ixx="2.159000e-04" ixy="-3.180614e-07" ixz="1.297688e-07" iyy="1.938000e-04" iyz="-2.499850e-05" izz="1.044000e-04"/>
    </inertial>
  </link>
  <!-- <gazebo reference="${prefix}eef_link_1">
        <collision name="collision">
            <surface>
            <contact>
                <collide_bitmask>0x01</collide_bitmask>
            </contact>
            </surface>
        </collision>
        </gazebo> -->
  <joint name="hand_eef_joint_1" type="revolute">
    <origin rpy="1.5707963267948966 0 1.5707963267948966" xyz="0.0165 0 0.0375"/>
    <parent link="hand_eef_link_1"/>
    <child link="hand_eef_link_2"/>
    <axis xyz="0 0 1"/>
    <limit effort="5.0" lower="0" upper="1.5707963267948966" velocity="10.0"/>
  </joint>
  <joint name="hand_crab_claw_joint" type="fixed">
    <origin rpy="1.5707963267948966 0 1.5707963267948966" xyz="0.0165 0 0.0375"/>
    <parent link="hand_eef_link_1"/>
    <child link="hand_crab_claw_center"/>
  </joint>
  <!-- Fixed at centered pose of crab claw, doesn't rotate, so its a stable reference -->
  <link name="hand_crab_claw_center">
    <!-- Super small interia to not effect dynamics and small rviz interia box -->
    <inertial>
      <mass value="0.0001"/>
      <origin rpy="0 0 0" xyz="0 0 0"/>
      <inertia ixx="0.001" ixy="0.00001" ixz="0.00001" iyy="0.001" iyz="0.00001" izz="0.001"/>
    </inertial>
  </link>
  <link name="hand_eef_link_2">
    <visual>
      <!-- rotate around a bit to close finger in starting position -->
      <!-- <origin rpy="0 0.204 0 " /> -->
      <geometry>
        <mesh filename="file:///home/bam/bam_ws/src/bam_common/bam_descriptions/urdf/crab_claw_v1/meshes/finger.stl"/>
      </geometry>
      <material name="StoglRobotics/LightGrey"/>
    </visual>
    <collision>
      <origin rpy="0 0 0" xyz="0 0 0"/>
      <geometry>
        <mesh filename="file:///home/bam/bam_ws/src/bam_common/bam_descriptions/urdf/crab_claw_v1/meshes/rotating_finger.stl"/>
      </geometry>
    </collision>
    <inertial>
      <origin xyz="-0.017182 0.044419 -0.009845"/>
      <mass value="0.029933"/>
      <inertia ixx="2.294500e-05" ixy="7.081339e-07" ixz="-5.446646e-07" iyy="5.181561e-06" iyz="3.769770e-06" izz="2.285568e-05"/>
    </inertial>
  </link>
  <gazebo reference="hand_eef_link_2">
    <selfCollide>'false'</selfCollide>
    <!-- <collision name="collision">
            <surface>
            <contact>
                <collide_bitmask>0x02</collide_bitmask>
            </contact>
            </surface>
        </collision> -->
  </gazebo>
  <link name="hand_tcp_world">
    <!-- Super small interia to not effect dynamics and small rviz interia box -->
    <inertial>
      <mass value="0.0001"/>
      <origin rpy="0 0 0" xyz="0 0 0"/>
      <inertia ixx="0.001" ixy="0.00001" ixz="0.00001" iyy="0.001" iyz="0.00001" izz="0.001"/>
    </inertial>
  </link>
  <link name="hand_tcp_tool">
    <!-- Super small interia to not effect dynamics and small rviz interia box -->
    <inertial>
      <mass value="0.0001"/>
      <origin rpy="0 0 0" xyz="0 0 0"/>
      <inertia ixx="0.001" ixy="0.00001" ixz="0.00001" iyy="0.001" iyz="0.00001" izz="0.001"/>
    </inertial>
  </link>
  <!-- Easier for Pick and Place as orientated with world -->
  <joint name="hand_joint_tcp_world" type="fixed">
    <origin rpy="3.141592653589793 0 0" xyz="0 0 0.144"/>
    <parent link="hand_eef_link_1"/>
    <child link="hand_tcp_world"/>
  </joint>
  <joint name="hand_joint_tcp_tool" type="fixed">
    <origin rpy="0 0 0" xyz="0 0 0.144"/>
    <parent link="hand_eef_link_1"/>
    <child link="hand_tcp_tool"/>
  </joint>
  <link name="hand_virtual_finger">
    <inertial>
      <mass value="1e-5"/>
      <origin rpy="0 0 0" xyz="0 0 0"/>
      <inertia ixx="1e-6" ixy="0.0" ixz="0.0" iyy="1e-6" iyz="0.0" izz="1e-6"/>
    </inertial>
  </link>
  <joint name="hand_joint_virtual_finger" type="revolute">
    <origin rpy="1.5707963267948966 0 1.5707963267948966" xyz="0.0165 0 0.0375"/>
    <parent link="hand_eef_link_1"/>
    <child link="hand_virtual_finger"/>
    <axis xyz="0 0 1"/>
    <mimic joint="hand_eef_joint_1" multiplier="0.5" offset="0.0"/>
    <limit effort="5.0" lower="0" upper="1.5707963267948966" velocity="10.0"/>
  </joint>
  <link name="hand_floating_tcp_world">
    <inertial>
      <mass value="1e-5"/>
      <origin rpy="0 0 0" xyz="0 0 0"/>
      <inertia ixx="1e-6" ixy="0.0" ixz="0.0" iyy="1e-6" iyz="0.0" izz="1e-6"/>
    </inertial>
  </link>
  <joint name="hand_joint_floating_tcp" type="fixed">
    <parent link="hand_virtual_finger"/>
    <child link="hand_floating_tcp_world"/>
    <origin rpy="1.5707963267948966 1.5707963267948966 0" xyz="0 0.1065 -0.0165"/>
  </joint>
  <joint name="arm_to_hand_mount" type="fixed">
    <origin rpy="0.0 -0.0 0.0" xyz="0.0 0.0 0.0"/>
    <parent link="arm_tool0"/>
    <child link="hand_eef_link_1"/>
  </joint>
</robot>
